Workbook
Name Prefix: DATA!$C$1
Name SignonBase: DATA!$I$1
Name UpdateID: DATA!$F$1

Sheet DATA
A1: =LEN(D1) -> 30 | B1: Prefix: | C1: UCCS_UXDSP_ | D1: =CONCATENATE(C1, A4) -> UCCS_UXDSP_STDNT_DISBLTY_SUPV2 | E1: Update ID: | F1: 1940408 | H1: Base signon PL: | I1: UC_SPSIGNON
A2: =LEN(C4) -> 22 | C2: Description | D2: =C4 -> STDT DISABILITY SUPV 2
A3: Permission List Name | B3: MARKET | C3: DESCR | D3: MENUNAME | E3: BARNAME | F3: ITEMNAME | G3: ITEMNAME_1 | H3: Display Only | I3: ACTIONS | J3: AU Access | K3: View | L3: ObjectownerID
A4: STDNT_DISBLTY_SUPV2 | B4: GBL | C4: STDT DISABILITY SUPV 2 | D4: CALCULATE_TUITION_AND_FEES | E4: INQUIRE | F4: FEES_AFTER_CALCULATION | G4: FEES_AFTER_CALCULATION | H4: 0 | I4: 2 | J4: 2
A5: STDNT_DISBLTY_SUPV2 | B5: GBL | C5: STDT DISABILITY SUPV 2 | D5: CALCULATE_TUITION_AND_FEES | E5: USE | F5: STDNT_EQUTN_VARS | G5: STDNT_EQUTIN_CHAR | H5: 1 | I5: 2 | J5: 2
A6: STDNT_DISBLTY_SUPV2 | B6: GBL | C6: STDT DISABILITY SUPV 2 | D6: CALCULATE_TUITION_AND_FEES | E6: USE | F6: STDNT_EQUTN_VARS | G6: STDNT_EQUTN_FLAG | H6: 1 | I6: 2 | J6: 2
A7: STDNT_DISBLTY_SUPV2 | B7: GBL | C7: STDT DISABILITY SUPV 2 | D7: CALCULATE_TUITION_AND_FEES | E7: USE | F7: STDNT_EQUTN_VARS | G7: STDNT_EQUTN_NUM | H7: 1 | I7: 2 | J7: 2
A8: STDNT_DISBLTY_SUPV2 | B8: GBL | C8: STDT DISABILITY SUPV 2 | D8: CALCULATE_TUITION_AND_FEES | E8: USE | F8: TUITION_CALC | G8: STDNT_TUITION_CALC | H8: 0 | I8: 2 | J8: 2
A9: STDNT_DISBLTY_SUPV2 | B9: GBL | C9: STDT DISABILITY SUPV 2 | D9: CC_BIO_DEMO_DATA_STDNT | E9: INQUIRE | F9: SCC_ADDR_PERS_INQ | G9: SCC_ADDR_PERS_INQ | H9: 1 | I9: 8 | J9: 8
A10: STDNT_DISBLTY_SUPV2 | B10: GBL | C10: STDT DISABILITY SUPV 2 | D10: CC_BIO_DEMO_DATA_STDNT | E10: INQUIRE | F10: SCC_EADDR_PERS_INQ | G10: SCC_EADDR_PERS_INQ | H10: 1 | I10: 8 | J10: 8
A11: STDNT_DISBLTY_SUPV2 | B11: GBL | C11: STDT DISABILITY SUPV 2 | D11: CC_BIO_DEMO_DATA_STDNT | E11: INQUIRE | F11: SCC_NAMES_INQ | G11: SCC_NAMES_INQ | H11: 1 | I11: 8 | J11: 8
A12: STDNT_DISBLTY_SUPV2 | B12: GBL | C12: STDT DISABILITY SUPV 2 | D12: CC_BIO_DEMO_DATA_STDNT | E12: INQUIRE | F12: SCC_PHONE_PERS_INQ | G12: SCC_PHONE_PERS_INQ | H12: 1 | I12: 8 | J12: 8
A13: STDNT_DISBLTY_SUPV2 | B13: GBL | C13: STDT DISABILITY SUPV 2 | D13: CC_BIO_DEMO_DATA_STDNT | E13: USE | F13: EMERGENCY_CONTACTS | G13: SCC_EMERG_CNTCT1 | H13: 1 | I13: 2 | J13: 2
A14: STDNT_DISBLTY_SUPV2 | B14: GBL | C14: STDT DISABILITY SUPV 2 | D14: CC_BIO_DEMO_DATA_STDNT | E14: USE | F14: EMERGENCY_CONTACTS | G14: SCC_EMERG_CNTCT2 | H14: 1 | I14: 2 | J14: 2
A15: STDNT_DISBLTY_SUPV2 | B15: GBL | C15: STDT DISABILITY SUPV 2 | D15: CC_BIO_DEMO_DATA_STDNT | E15: USE | F15: ETHNICITY_DETAIL | G15: ETHNICITY_DETAIL | H15: 1 | I15: 2 | J15: 2
... A253: STDNT_DISBLTY_SUPV2 | B253: GBL | C253: STDT DISABILITY SUPV 2 | D253: XMLPUBLISHER | E253: USE | F253: PSXP_REPORTMGR | G253: PSXPRPTMGR | H253: 0 | I253: 2 | J253: 2

Sheet Sheet1

Sheet Auth Access
A1: PAGEACCESSDESCR | B1: If this | C1: Than AU
A2: Add | B2: 1 | C2: 1
A3: Update/Display | B3: 2 | C3: 2
A4: Add Update/Display | B4: 3 | C4: 2
A5: Update/Display All | B5: 4 | C5: 4
A6: Add Update/Display All | B6: 5 | C6: 4
A7: Update/Display Update/Display All | B7: 6 | C7: 6
A8: Add Update/Display Update/Display All | B8: 7 | C8: 6
A9: Correction | B9: 8 | C9: 8
A10: Add Correction | B10: 9 | C10: 8
A11: Update/Display Correction | B11: 10 | C11: 2
A12: Add Update/Display Correction | B12: 11 | C12: 2
A13: Update/Display All Correction | B13: 12 | C13: 4
... A32: Add Update/Display Update/Display All Correction Data Entry | B32: 143 | C32: 6

Sheet SQL Statement
A1: SQL Statement
A2: select a.pnlgrpname, b.market, a.descr, c.menuname, c.barname, c.itemname, B.ITEMNAME, a.actions from pspnlgroup b, pspnlgrpdefn a, psmenuitem c where a.pnlgrpname = b.pnlgrpname and a.market = b.market and a.market = c.market and c.pnlgrpname = a.pnlgrpname and a.pnlgrpname IN ('PSXPSETUPRPTCAT', 'PSXPSETUPDWNLD', 'PSXPDATASRC', 'PSXPRPTDEFN', 'PSXPSUBTMPLDEFN', 'PSXPTMPLTRNS', 'PSXPQRYVIEWER', 'PSXPRUNQRYRPT', 'PSXP_REPORTMGR') order by 1, 2, 3, 4
A4: Process Group SQL
A5: select * from PS_PRCSDEFNPNL a, ps_PRCSDEFNGRP b where a.pnlgrpname in ('UW_CLN_BATCH_CLNS', 'ISIR_SUSP_CNTRL_17', 'INAS_IM_SMRY_14', 'ISIR_EFC_SMRY_DT14', 'PROFILE_DATA_14', 'INAS_IM_SMRY_17', 'INAS_SIMULATION_17', 'ISIR_CORRPIA17', 'ISIR_EFC_SMRY_DT17', 'LOCAL_POLICY_PT_17', 'PROFILE_DATA_17', 'SFA_ATB_CODE_XREF') and a.prcstype = b.prcstype and a.prcsname = b.prcsname;

Sheet AuthActionsTable
A1: AUTHORIZEDACTIONS | B1: PAGEACCESSDESCR | C1: View Access should be: | D1: Includes Add | E1: AU Access
A2: 1 | B2: Add | C2: 1 | D2: A | E2: 1
A3: 2 | B3: Update/Display | C3: 2 | E3: 2
A4: 3 | B4: Add Update/Display | C4: 2 | D4: A | E4: 3
A5: 4 | B5: Update/Display All | C5: 4 | E5: 4
A6: 5 | B6: Add Update/Display All | C6: 4 | D6: A | E6: 5
A7: 6 | B7: Update/Display Update/Display All | C7: 6 | E7: 6
A8: 7 | B8: Add Update/Display Update/Display All | C8: 6 | D8: A | E8: 7
A9: 8 | B9: Correction | C9: 8 | E9: 8
A10: 9 | B10: Add Correction | C10: 8 | D10: A | E10: 1
A11: 10 | B11: Update/Display Correction | C11: 2 | E11: 2
A12: 11 | B12: Add Update/Display Correction | C12: 2 | D12: A | E12: 3
A13: 12 | B13: Update/Display All Correction | C13: 4 | E13: 4
A14: 13 | B14: Add Update/Display All Correction | C14: 4 | D14: A | E14: 5
A15: 14 | B15: Update/Display Update/Display All Correction | C15: 6 | E15: 6
A16: 15 | B16: Add Update/Display Update/Display All Correction | C16: 6 | D16: A | E16: 7
A17: 128 | B17: Data Entry | C17: 128 | E17: 128
A18: 129 | B18: Add Data Entry | C18: 128 | D18: A | E18: 129
A19: 130 | B19: Update/Display Data Entry | C19: 130 | E19: 130
A20: 131 | B20: Add Update/Display Data Entry | C20: 130 | D20: A | E20: 131
A21: 132 | B21: Update/Display All Data Entry | C21: 132 | E21: 132
A22: 133 | B22: Add Update/Display All Data Entry | C22: 132 | D22: A | E22: 133
A23: 134 | B23: Update/Display Update/Display All Data Entry | C23: 134 | E23: 134
A24: 135 | B24: Add Update/Display Update/Display All Data Entry | C24: 134 | D24: A | E24: 135
A25: 136 | B25: Correction Data Entry | C25: 128 | E25: 128
A26: 137 | B26: Add Correction Data Entry | C26: 128 | D26: A | E26: 129
A27: 138 | B27: Update/Display Correction Data Entry | C27: 130 | E27: 130
A28: 139 | B28: Add Update/Display Correction Data Entry | C28: 130 | D28: A | E28: 130
A29: 140 | B29: Update/Display All Correction Data Entry | C29: 132 | E29: 132
A30: 141 | B30: Add Update/Display All Correction Data Entry | C30: 132 | D30: A | E30: 133
A31: 142 | B31: Update/Display Update/Display All Correction Data Entry | C31: 134 | E31: 134
A32: 143 | B32: Add Update/Display Update/Display All Correction Data Entry | C32: 134 | D32: A | E32: 135

Sheet SQL Statements
A4: =CLASSDEFN_AU!A4 -> INSERT INTO SYSADM.PSCLASSDEFN VALUES('UCCS_UXDSP_STDNT_DISBLTY_SUPV2', (SELECT VERSION FROM SYSADM.PSVERSION WHERE OBJECTTYPENAME = 'CLM'), 'STDT DISABILITY SUPV 2', 30, ' ', 0, 0, SYSDATE, '1940408');
A5: =SIGNON_AU!A4 -> INSERT INTO SYSADM.PSAUTHSIGNON SELECT 'UCCS_UXDSP_STDNT_DISBLTY_SUPV2', DAYOFWEEK, STARTTIME, ENDTIME FROM SYSADM.PSAUTHSIGNON WHERE CLASSID = 'UC_SPSIGNON';
A6: =PSPRCSPRFL!A4 -> INSERT INTO SYSADM.PSPRCSPRFL SELECT 'UCCS_UXDSP_STDNT_DISBLTY_SUPV2', SRVRDESTFILE, SRVRDESTPRNT, CLIENTDESTFILE, CLIENTDESTPRNT, OVRDOUTDEST, OVRDSRVRPARMS, RQSTSTATUSUPD, RQSTSTATUSVIEW, SRVRSTATUSUPD, SRVRSTATUSVIEW, MVSJOBNAME, MVSJOBACCT, RECURUPD FROM SYSADM.PSPRCSPRFL WHERE CLASSID = 'UC_SPSIGNON';
A7: =SCRTY_QUERY!A4 -> INSERT INTO SYSADM.PS_SCRTY_QUERY SELECT 'UCCS_UXDSP_STDNT_DISBLTY_SUPV2', (SELECT VERSION FROM SYSADM.PSVERSION WHERE OBJECTTYPENAME = 'CLM'), QRY_RUN_ONLY, QRY_CREATE_PUBLIC, QRY_CREATE_WFLOW, QRY_MAX_FETCH, QRY_MAX_RUN, QRY_ADV_DISTINCT, QRY_ADV_ANY_JOIN, QRY_ADV_SUBQUERY, QRY_ADV_UNION, QRY_ADV_EXPR, QRY_MAX_JOINS, QRY_MAX_IN_TREE, QRY_OUT_LISTBOX, QRY_OUT_NVISION, QRY_OUT_CRYSTAL, QRY_ADM_AUTOPUBLIC, QRY_ADM_AUTOPRIV, QRY_ADM_LIMUNAPPRV, QRY_ADM_UNAPP_ROWS FROM SYSADM.PS_SCRTY_QUERY WHERE CLASSID ='UC_CS_BASE_USER';
A8: =PSPTSCRTY_ADS_P!A4 -> INSERT INTO SYSADM.PSPTSCRTY_ADS_P VALUES( 'UCCS_UXDSP_STDNT_DISBLTY_SUPV2', 'NO', 'N', 'NO');
A9: =MC_OPRID!A4 -> INSERT INTO SYSADM.PS_MC_OPRID VALUES('UCCS_UXDSP_STDNT_DISBLTY_SUPV2','N');
A12: =PSAUTHITEM_AU!A4 -> INSERT INTO SYSADM.PSAUTHITEM VALUES ('UCCS_UXDSP_STDNT_DISBLTY_SUPV2', 'CALCULATE_TUITION_AND_FEES', 'INQUIRE', 'FEES_AFTER_CALCULATION', 'FEES_AFTER_CALCULATION', '0', 2);
A13: =PSAUTHITEM_AU!A5 -> INSERT INTO SYSADM.PSAUTHITEM VALUES ('UCCS_UXDSP_STDNT_DISBLTY_SUPV2', 'CALCULATE_TUITION_AND_FEES', 'USE', 'STDNT_EQUTN_VARS', 'STDNT_EQUTIN_CHAR', '1', 2);
A14: =PSAUTHITEM_AU!A6 -> INSERT INTO SYSADM.PSAUTHITEM VALUES ('UCCS_UXDSP_STDNT_DISBLTY_SUPV2', 'CALCULATE_TUITION_AND_FEES', 'USE', 'STDNT_EQUTN_VARS', 'STDNT_EQUTN_FLAG', '1', 2);
A15: =PSAUTHITEM_AU!A7 -> INSERT INTO SYSADM.PSAUTHITEM VALUES ('UCCS_UXDSP_STDNT_DISBLTY_SUPV2', 'CALCULATE_TUITION_AND_FEES', 'USE', 'STDNT_EQUTN_VARS', 'STDNT_EQUTN_NUM', '1', 2);
A16: =PSAUTHITEM_AU!A8 -> INSERT INTO SYSADM.PSAUTHITEM VALUES ('UCCS_UXDSP_STDNT_DISBLTY_SUPV2', 'CALCULATE_TUITION_AND_FEES', 'USE', 'TUITION_CALC', 'STDNT_TUITION_CALC', '0', 2);
A17: =PSAUTHITEM_AU!A9 -> INSERT INTO SYSADM.PSAUTHITEM VALUES ('UCCS_UXDSP_STDNT_DISBLTY_SUPV2', 'CC_BIO_DEMO_DATA_STDNT', 'INQUIRE', 'SCC_ADDR_PERS_INQ', 'SCC_ADDR_PERS_INQ', '1', 8);
A18: =PSAUTHITEM_AU!A10 -> INSERT INTO SYSADM.PSAUTHITEM VALUES ('UCCS_UXDSP_STDNT_DISBLTY_SUPV2', 'CC_BIO_DEMO_DATA_STDNT', 'INQUIRE', 'SCC_EADDR_PERS_INQ', 'SCC_EADDR_PERS_INQ', '1', 8);
A19: =PSAUTHITEM_AU!A11 -> INSERT INTO SYSADM.PSAUTHITEM VALUES ('UCCS_UXDSP_STDNT_DISBLTY_SUPV2', 'CC_BIO_DEMO_DATA_STDNT', 'INQUIRE', 'SCC_NAMES_INQ', 'SCC_NAMES_INQ', '1', 8);
A20: =PSAUTHITEM_AU!A12 -> INSERT INTO SYSADM.PSAUTHITEM VALUES ('UCCS_UXDSP_STDNT_DISBLTY_SUPV2', 'CC_BIO_DEMO_DATA_STDNT', 'INQUIRE', 'SCC_PHONE_PERS_INQ', 'SCC_PHONE_PERS_INQ', '1', 8);
A21: =PSAUTHITEM_AU!A13 -> INSERT INTO SYSADM.PSAUTHITEM VALUES ('UCCS_UXDSP_STDNT_DISBLTY_SUPV2', 'CC_BIO_DEMO_DATA_STDNT', 'USE', 'EMERGENCY_CONTACTS', 'SCC_EMERG_CNTCT1', '1', 2);
A22: =PSAUTHITEM_AU!A14 -> INSERT INTO SYSADM.PSAUTHITEM VALUES ('UCCS_UXDSP_STDNT_DISBLTY_SUPV2', 'CC_BIO_DEMO_DATA_STDNT', 'USE', 'EMERGENCY_CONTACTS', 'SCC_EMERG_CNTCT2', '1', 2);
A23: =PSAUTHITEM_AU!A15 -> INSERT INTO SYSADM.PSAUTHITEM VALUES ('UCCS_UXDSP_STDNT_DISBLTY_SUPV2', 'CC_BIO_DEMO_DATA_STDNT', 'USE', 'ETHNICITY_DETAIL', 'ETHNICITY_DETAIL', '1', 2);
... A1244: =PSAUTHITEM_AU!A1236

Sheet CLASSDEFN_AU
A1: User | B1: =UpdateID -> 1940408
A3: SQL Statement
A4: =IF(AND(NOT(ISBLANK(DATA!A4)),DATA!A4<>DATA!A3),"INSERT INTO SYSADM.PSCLASSDEFN VALUES('"&PSAUTHITEM_AU!$B$1 & DATA!A4&"', (SELECT VERSION FROM SYSADM.PSVERSION WHERE OBJECTTYPENAME = 'CLM'), '"&IF(DATA!C4=" ",DATA!A4,DATA!C4)&"', 30, ' ', 0, 0, SYSDATE, '"&UpdateID&"');","") -> INSERT INTO SYSADM.PSCLASSDEFN VALUES('UCCS_UXDSP_STDNT_DISBLTY_SUPV2', (SELECT VERSION FROM SYSADM.PSVERSION WHERE OBJECTTYPENAME = 'CLM'), 'STDT DISABILITY SUPV 2', 30, ' ', 0, 0, SYSDATE, '1940408');
A5: =IF(AND(NOT(ISBLANK(DATA!A5)),DATA!A5<>DATA!A4),"INSERT INTO SYSADM.PSCLASSDEFN VALUES('"&PSAUTHITEM_AU!$B$1 & DATA!A5&", (SELECT VERSION FROM SYSADM.PSVERSION WHERE OBJECTTYPENAME = 'CLM'), '"&IF(DATA!C5=" ",DATA!A5,DATA!C5)&"', 30, ' ', 0, 0, SYSDATE, '"&UpdateID&"');","")
A6: =IF(AND(NOT(ISBLANK(DATA!A6)),DATA!A6<>DATA!A5),"INSERT INTO SYSADM.PSCLASSDEFN VALUES('"&PSAUTHITEM_AU!$B$1 & DATA!A6&", (SELECT VERSION FROM SYSADM.PSVERSION WHERE OBJECTTYPENAME = 'CLM'), '"&IF(DATA!C6=" ",DATA!A6,DATA!C6)&"', 30, ' ', 0, 0, SYSDATE, '"&UpdateID&"');","")
A7: =IF(AND(NOT(ISBLANK(DATA!A7)),DATA!A7<>DATA!A6),"INSERT INTO SYSADM.PSCLASSDEFN VALUES('"&PSAUTHITEM_AU!$B$1 & DATA!A7&", (SELECT VERSION FROM SYSADM.PSVERSION WHERE OBJECTTYPENAME = 'CLM'), '"&IF(DATA!C7=" ",DATA!A7,DATA!C7)&"', 30, ' ', 0, 0, SYSDATE, '"&UpdateID&"');","")
A8: =IF(AND(NOT(ISBLANK(DATA!A8)),DATA!A8<>DATA!A7),"INSERT INTO SYSADM.PSCLASSDEFN VALUES('"&PSAUTHITEM_AU!$B$1 & DATA!A8&", (SELECT VERSION FROM SYSADM.PSVERSION WHERE OBJECTTYPENAME = 'CLM'), '"&IF(DATA!C8=" ",DATA!A8,DATA!C8)&"', 30, ' ', 0, 0, SYSDATE, '"&UpdateID&"');","")
A9: =IF(AND(NOT(ISBLANK(DATA!A9)),DATA!A9<>DATA!A8),"INSERT INTO SYSADM.PSCLASSDEFN VALUES('"&PSAUTHITEM_AU!$B$1 & DATA!A9&", (SELECT VERSION FROM SYSADM.PSVERSION WHERE OBJECTTYPENAME = 'CLM'), '"&IF(DATA!C9=" ",DATA!A9,DATA!C9)&"', 30, ' ', 0, 0, SYSDATE, '"&UpdateID&"');","")
A10: =IF(AND(NOT(ISBLANK(DATA!A10)),DATA!A10<>DATA!A9),"INSERT INTO SYSADM.PSCLASSDEFN VALUES('"&PSAUTHITEM_AU!$B$1 & DATA!A10&", (SELECT VERSION FROM SYSADM.PSVERSION WHERE OBJECTTYPENAME = 'CLM'), '"&IF(DATA!C10=" ",DATA!A10,DATA!C10)&"', 30, ' ', 0, 0, SYSDATE, '"&UpdateID&"');","")
A11: =IF(AND(NOT(ISBLANK(DATA!A11)),DATA!A11<>DATA!A10),"INSERT INTO SYSADM.PSCLASSDEFN VALUES('"&PSAUTHITEM_AU!$B$1 & DATA!A11&", (SELECT VERSION FROM SYSADM.PSVERSION WHERE OBJECTTYPENAME = 'CLM'), '"&IF(DATA!C11=" ",DATA!A11,DATA!C11)&"', 30, ' ', 0, 0, SYSDATE, '"&UpdateID&"');","")
A12: =IF(AND(NOT(ISBLANK(DATA!A12)),DATA!A12<>DATA!A11),"INSERT INTO SYSADM.PSCLASSDEFN VALUES('"&PSAUTHITEM_AU!$B$1 & DATA!A12&", (SELECT VERSION FROM SYSADM.PSVERSION WHERE OBJECTTYPENAME = 'CLM'), '"&IF(DATA!C12=" ",DATA!A12,DATA!C12)&"', 30, ' ', 0, 0, SYSDATE, '"&UpdateID&"');","")
A13: =IF(AND(NOT(ISBLANK(DATA!A13)),DATA!A13<>DATA!A12),"INSERT INTO SYSADM.PSCLASSDEFN VALUES('"&PSAUTHITEM_AU!$B$1 & DATA!A13&", (SELECT VERSION FROM SYSADM.PSVERSION WHERE OBJECTTYPENAME = 'CLM'), '"&IF(DATA!C13=" ",DATA!A13,DATA!C13)&"', 30, ' ', 0, 0, SYSDATE, '"&UpdateID&"');","")
A14: =IF(AND(NOT(ISBLANK(DATA!A14)),DATA!A14<>DATA!A13),"INSERT INTO SYSADM.PSCLASSDEFN VALUES('"&PSAUTHITEM_AU!$B$1 & DATA!A14&", (SELECT VERSION FROM SYSADM.PSVERSION WHERE OBJECTTYPENAME = 'CLM'), '"&IF(DATA!C14=" ",DATA!A14,DATA!C14)&"', 30, ' ', 0, 0, SYSDATE, '"&UpdateID&"');","")
A15: =IF(AND(NOT(ISBLANK(DATA!A15)),DATA!A15<>DATA!A14),"INSERT INTO SYSADM.PSCLASSDEFN VALUES('"&PSAUTHITEM_AU!$B$1 & DATA!A15&", (SELECT VERSION FROM SYSADM.PSVERSION WHERE OBJECTTYPENAME = 'CLM'), '"&IF(DATA!C15=" ",DATA!A15,DATA!C15)&"', 30, ' ', 0, 0, SYSDATE, '"&UpdateID&"');","")
A16: =IF(AND(NOT(ISBLANK(DATA!A16)),DATA!A16<>DATA!A15),"INSERT INTO SYSADM.PSCLASSDEFN VALUES('"&PSAUTHITEM_AU!$B$1 & DATA!A16&", (SELECT VERSION FROM SYSADM.PSVERSION WHERE OBJECTTYPENAME = 'CLM'), '"&IF(DATA!C16=" ",DATA!A16,DATA!C16)&"', 30, ' ', 0, 0, SYSDATE, '"&UpdateID&"');","")
... A30: =IF(AND(NOT(ISBLANK(DATA!A30)),DATA!A30<>DATA!A29),"INSERT INTO SYSADM.PSCLASSDEFN VALUES('"&PSAUTHITEM_AU!$B$1 & DATA!A30&", (SELECT VERSION FROM SYSADM.PSVERSION WHERE OBJECTTYPENAME = 'CLM'), '"&IF(DATA!C30=" ",DATA!A30,DATA!C30)&"', 30, ' ', 0, 0, SYSDATE, '"&UpdateID&"');","")
A31: =IF(AND(NOT(ISBLANK(DATA!A29)),DATA!A29<>DATA!A28),"INSERT INTO SYSADM.PSCLASSDEFN VALUES('"&PSAUTHITEM_AU!$B$1 & DATA!A29&", (SELECT VERSION FROM SYSADM.PSVERSION WHERE OBJECTTYPENAME = 'CLM'), '"&IF(DATA!C29=" ",DATA!A29,DATA!C29)&"', 30, ' ', 0, 0, SYSDATE, '"&UpdateID&"');","")
A32: =IF(AND(NOT(ISBLANK(DATA!A30)),DATA!A30<>DATA!A29),"INSERT INTO SYSADM.PSCLASSDEFN VALUES('"&PSAUTHITEM_AU!$B$1 & DATA!A30&", (SELECT VERSION FROM SYSADM.PSVERSION WHERE OBJECTTYPENAME = 'CLM'), '"&IF(DATA!C30=" ",DATA!A30,DATA!C30)&"', 30, ' ', 0, 0, SYSDATE, '"&UpdateID&"');","")
A33: =IF(AND(NOT(ISBLANK(DATA!A31)),DATA!A31<>DATA!A30),"INSERT INTO SYSADM.PSCLASSDEFN VALUES('"&PSAUTHITEM_AU!$B$1 & DATA!A31&", (SELECT VERSION FROM SYSADM.PSVERSION WHERE OBJECTTYPENAME = 'CLM'), '"&IF(DATA!C31=" ",DATA!A31,DATA!C31)&"', 30, ' ', 0, 0, SYSDATE, '"&UpdateID&"');","")
A34: =IF(AND(NOT(ISBLANK(DATA!A32)),DATA!A32<>DATA!A31),"INSERT INTO SYSADM.PSCLASSDEFN VALUES('"&PSAUTHITEM_AU!$B$1 & DATA!A32&", (SELECT VERSION FROM SYSADM.PSVERSION WHERE OBJECTTYPENAME = 'CLM'), '"&IF(DATA!C32=" ",DATA!A32,DATA!C32)&"', 30, ' ', 0, 0, SYSDATE, '"&UpdateID&"');","")
A35: =IF(AND(NOT(ISBLANK(DATA!A33)),DATA!A33<>DATA!A32),"INSERT INTO SYSADM.PSCLASSDEFN VALUES('"&PSAUTHITEM_AU!$B$1 & DATA!A33&", (SELECT VERSION FROM SYSADM.PSVERSION WHERE OBJECTTYPENAME = 'CLM'), '"&IF(DATA!C33=" ",DATA!A33,DATA!C33)&"', 30, ' ', 0, 0, SYSDATE, '"&UpdateID&"');","")
A36: =IF(AND(NOT(ISBLANK(DATA!A34)),DATA!A34<>DATA!A33),"INSERT INTO SYSADM.PSCLASSDEFN VALUES('"&PSAUTHITEM_AU!$B$1 & DATA!A34&", (SELECT VERSION FROM SYSADM.PSVERSION WHERE OBJECTTYPENAME = 'CLM'), '"&IF(DATA!C34=" ",DATA!A34,DATA!C34)&"', 30, ' ', 0, 0, SYSDATE, '"&UpdateID&"');","")
A37: =IF(AND(NOT(ISBLANK(DATA!A35)),DATA!A35<>DATA!A34),"INSERT INTO SYSADM.PSCLASSDEFN VALUES('"&PSAUTHITEM_AU!$B$1 & DATA!A35&", (SELECT VERSION FROM SYSADM.PSVERSION WHERE OBJECTTYPENAME = 'CLM'), '"&IF(DATA!C35=" ",DATA!A35,DATA!C35)&"', 30, ' ', 0, 0, SYSDATE, '"&UpdateID&"');","")
A38: =IF(AND(NOT(ISBLANK(DATA!A36)),DATA!A36<>DATA!A35),"INSERT INTO SYSADM.PSCLASSDEFN VALUES('"&PSAUTHITEM_AU!$B$1 & DATA!A36&", (SELECT VERSION FROM SYSADM.PSVERSION WHERE OBJECTTYPENAME = 'CLM'), '"&IF(DATA!C36=" ",DATA!A36,DATA!C36)&"', 30, ' ', 0, 0, SYSDATE, '"&UpdateID&"');","")
A39: =IF(AND(NOT(ISBLANK(DATA!A37)),DATA!A37<>DATA!A36),"INSERT INTO SYSADM.PSCLASSDEFN VALUES('"&PSAUTHITEM_AU!$B$1 & DATA!A37&", (SELECT VERSION FROM SYSADM.PSVERSION WHERE OBJECTTYPENAME = 'CLM'), '"&IF(DATA!C37=" ",DATA!A37,DATA!C37)&"', 30, ' ', 0, 0, SYSDATE, '"&UpdateID&"');","")
A40: =IF(AND(NOT(ISBLANK(DATA!A38)),DATA!A38<>DATA!A37),"INSERT INTO SYSADM.PSCLASSDEFN VALUES('"&PSAUTHITEM_AU!$B$1 & DATA!A38&", (SELECT VERSION FROM SYSADM.PSVERSION WHERE OBJECTTYPENAME = 'CLM'), '"&IF(DATA!C38=" ",DATA!A38,DATA!C38)&"', 30, ' ', 0, 0, SYSDATE, '"&UpdateID&"');","")
A41: =IF(AND(NOT(ISBLANK(DATA!A39)),DATA!A39<>DATA!A38),"INSERT INTO SYSADM.PSCLASSDEFN VALUES('"&PSAUTHITEM_AU!$B$1 & DATA!A39&", (SELECT VERSION FROM SYSADM.PSVERSION WHERE OBJECTTYPENAME = 'CLM'), '"&IF(DATA!C39=" ",DATA!A39,DATA!C39)&"', 30, ' ', 0, 0, SYSDATE, '"&UpdateID&"');","")
A42: =IF(AND(NOT(ISBLANK(DATA!A40)),DATA!A40<>DATA!A39),"INSERT INTO SYSADM.PSCLASSDEFN VALUES('"&PSAUTHITEM_AU!$B$1 & DATA!A40&", (SELECT VERSION FROM SYSADM.PSVERSION WHERE OBJECTTYPENAME = 'CLM'), '"&IF(DATA!C40=" ",DATA!A40,DATA!C40)&"', 30, ' ', 0, 0, SYSDATE, '"&UpdateID&"');","")
... A2000: =IF(AND(NOT(ISBLANK(DATA!A1998)),DATA!A1998<>DATA!A1997),"INSERT INTO SYSADM.PSCLASSDEFN VALUES('"&PSAUTHITEM_AU!$B$1 & DATA!A1998&", (SELECT VERSION FROM SYSADM.PSVERSION WHERE OBJECTTYPENAME = 'CLM'), '"&IF(DATA!C1998=" ",DATA!A1998,DATA!C1998)&"', 30, ' ', 0, 0, SYSDATE, '"&UpdateID&"');","")

Sheet CLASSDEFN_VW
A1: User | B1: =UpdateID -> 1940408
A3: SQL Statement
A4: =IF(AND(NOT(ISBLANK(DATA!A4)),DATA!A4<>DATA!A3),"INSERT INTO SYSADM.PSCLASSDEFN VALUES ('"&PSAUTHITEM_AU!$B$1 & DATA!A4&"_VW', "&"(SELECT VERSION FROM SYSADM.PSVERSION WHERE OBJECTTYPENAME = 'CLM'), '"&DATA!C4&"', 0, ' ', 30, 0, SYSDATE, '"&CLASSDEFN_VW!$B$1&"');","") -> INSERT INTO SYSADM.PSCLASSDEFN VALUES ('UCCS_UXDSP_STDNT_DISBLTY_SUPV2_VW', (SELECT VERSION FROM SYSADM.PSVERSION WHERE OBJECTTYPENAME = 'CLM'), 'STDT DISABILITY SUPV 2', 0, ' ', 30, 0, SYSDATE, '1940408');
A5: =IF(AND(NOT(ISBLANK(DATA!A5)),DATA!A5<>DATA!A4),"INSERT INTO SYSADM.PSCLASSDEFN VALUES ('"&PSAUTHITEM_AU!$B$1 & DATA!A5&"_VW', "&"(SELECT VERSION FROM SYSADM.PSVERSION WHERE OBJECTTYPENAME = 'CLM'), '"&DATA!C5&"', 0, ' ', 30, 0, SYSDATE, '"&CLASSDEFN_VW!$B$1&"');","")
A6: =IF(AND(NOT(ISBLANK(DATA!#REF!)),DATA!#REF!<>DATA!A5),"INSERT INTO SYSADM.PSCLASSDEFN VALUES ('"&PSAUTHITEM_AU!$B$1 & DATA!#REF!&"_VW', "&"(SELECT VERSION FROM SYSADM.PSVERSION WHERE OBJECTTYPENAME = 'CLM'), '"&DATA!#REF!&"', 0, ' ', 30, 0, SYSDATE, '"&CLASSDEFN_VW!$B$1&"');","") -> #REF!
A7: =IF(AND(NOT(ISBLANK(DATA!#REF!)),DATA!#REF!<>DATA!#REF!),"INSERT INTO SYSADM.PSCLASSDEFN VALUES ('"&PSAUTHITEM_AU!$B$1 & DATA!#REF!&"_VW', "&"(SELECT VERSION FROM SYSADM.PSVERSION WHERE OBJECTTYPENAME = 'CLM'), '"&DATA!#REF!&"', 0, ' ', 30, 0, SYSDATE, '"&CLASSDEFN_VW!$B$1&"');","") -> #REF!
A8: =IF(AND(NOT(ISBLANK(DATA!A6)),DATA!A6<>DATA!#REF!),"INSERT INTO SYSADM.PSCLASSDEFN VALUES ('"&PSAUTHITEM_AU!$B$1 & DATA!A6&"_VW', "&"(SELECT VERSION FROM SYSADM.PSVERSION WHERE OBJECTTYPENAME = 'CLM'), '"&DATA!C6&"', 0, ' ', 30, 0, SYSDATE, '"&CLASSDEFN_VW!$B$1&"');","") -> #REF!
A9: =IF(AND(NOT(ISBLANK(DATA!A7)),DATA!A7<>DATA!A6),"INSERT INTO SYSADM.PSCLASSDEFN VALUES ('"&PSAUTHITEM_AU!$B$1 & DATA!A7&"_VW', "&"(SELECT VERSION FROM SYSADM.PSVERSION WHERE OBJECTTYPENAME = 'CLM'), '"&DATA!C7&"', 0, ' ', 30, 0, SYSDATE, '"&CLASSDEFN_VW!$B$1&"');","")
A10: =IF(AND(NOT(ISBLANK(DATA!A8)),DATA!A8<>DATA!A7),"INSERT INTO SYSADM.PSCLASSDEFN VALUES ('"&PSAUTHITEM_AU!$B$1 & DATA!A8&"_VW', "&"(SELECT VERSION FROM SYSADM.PSVERSION WHERE OBJECTTYPENAME = 'CLM'), '"&DATA!C8&"', 0, ' ', 30, 0, SYSDATE, '"&CLASSDEFN_VW!$B$1&"');","")
A11: =IF(AND(NOT(ISBLANK(DATA!A9)),DATA!A9<>DATA!A8),"INSERT INTO SYSADM.PSCLASSDEFN VALUES ('"&PSAUTHITEM_AU!$B$1 & DATA!A9&"_VW', "&"(SELECT VERSION FROM SYSADM.PSVERSION WHERE OBJECTTYPENAME = 'CLM'), '"&DATA!C9&"', 0, ' ', 30, 0, SYSDATE, '"&CLASSDEFN_VW!$B$1&"');","")
A12: =IF(AND(NOT(ISBLANK(DATA!A10)),DATA!A10<>DATA!A9),"INSERT INTO SYSADM.PSCLASSDEFN VALUES ('"&PSAUTHITEM_AU!$B$1 & DATA!A10&"_VW', "&"(SELECT VERSION FROM SYSADM.PSVERSION WHERE OBJECTTYPENAME = 'CLM'), '"&DATA!C10&"', 0, ' ', 30, 0, SYSDATE, '"&CLASSDEFN_VW!$B$1&"');","")
A13: =IF(AND(NOT(ISBLANK(DATA!A11)),DATA!A11<>DATA!A10),"INSERT INTO SYSADM.PSCLASSDEFN VALUES ('"&PSAUTHITEM_AU!$B$1 & DATA!A11&"_VW', "&"(SELECT VERSION FROM SYSADM.PSVERSION WHERE OBJECTTYPENAME = 'CLM'), '"&DATA!C11&"', 0, ' ', 30, 0, SYSDATE, '"&CLASSDEFN_VW!$B$1&"');","")
A14: =IF(AND(NOT(ISBLANK(DATA!A12)),DATA!A12<>DATA!A11),"INSERT INTO SYSADM.PSCLASSDEFN VALUES ('"&PSAUTHITEM_AU!$B$1 & DATA!A12&"_VW', "&"(SELECT VERSION FROM SYSADM.PSVERSION WHERE OBJECTTYPENAME = 'CLM'), '"&DATA!C12&"', 0, ' ', 30, 0, SYSDATE, '"&CLASSDEFN_VW!$B$1&"');","")
A15: =IF(AND(NOT(ISBLANK(DATA!A13)),DATA!A13<>DATA!A12),"INSERT INTO SYSADM.PSCLASSDEFN VALUES ('"&PSAUTHITEM_AU!$B$1 & DATA!A13&"_VW', "&"(SELECT VERSION FROM SYSADM.PSVERSION WHERE OBJECTTYPENAME = 'CLM'), '"&DATA!C13&"', 0, ' ', 30, 0, SYSDATE, '"&CLASSDEFN_VW!$B$1&"');","")
A16: =IF(AND(NOT(ISBLANK(DATA!A14)),DATA!A14<>DATA!A13),"INSERT INTO SYSADM.PSCLASSDEFN VALUES ('"&PSAUTHITEM_AU!$B$1 & DATA!A14&"_VW', "&"(SELECT VERSION FROM SYSADM.PSVERSION WHERE OBJECTTYPENAME = 'CLM'), '"&DATA!C14&"', 0, ' ', 30, 0, SYSDATE, '"&CLASSDEFN_VW!$B$1&"');","")
A17: =IF(AND(NOT(ISBLANK(DATA!A15)),DATA!A15<>DATA!A14),"INSERT INTO SYSADM.PSCLASSDEFN VALUES ('"&PSAUTHITEM_AU!$B$1 & DATA!A15&"_VW', "&"(SELECT VERSION FROM SYSADM.PSVERSION WHERE OBJECTTYPENAME = 'CLM'), '"&DATA!C15&"', 0, ' ', 30, 0, SYSDATE, '"&CLASSDEFN_VW!$B$1&"');","")
A18: =IF(AND(NOT(ISBLANK(DATA!A16)),DATA!A16<>DATA!A15),"INSERT INTO SYSADM.PSCLASSDEFN VALUES ('"&PSAUTHITEM_AU!$B$1 & DATA!A16&"_VW', "&"(SELECT VERSION FROM SYSADM.PSVERSION WHERE OBJECTTYPENAME = 'CLM'), '"&DATA!C16&"', 0, ' ', 30, 0, SYSDATE, '"&CLASSDEFN_VW!$B$1&"');","")
A19: =IF(AND(NOT(ISBLANK(DATA!A17)),DATA!A17<>DATA!A16),"INSERT INTO SYSADM.PSCLASSDEFN VALUES ('"&PSAUTHITEM_AU!$B$1 & DATA!A17&"_VW', "&"(SELECT VERSION FROM SYSADM.PSVERSION WHERE OBJECTTYPENAME = 'CLM'), '"&DATA!C17&"', 0, ' ', 30, 0, SYSDATE, '"&CLASSDEFN_VW!$B$1&"');","")
A20: =IF(AND(NOT(ISBLANK(DATA!A18)),DATA!A18<>DATA!A17),"INSERT INTO SYSADM.PSCLASSDEFN VALUES ('"&PSAUTHITEM_AU!$B$1 & DATA!A18&"_VW', "&"(SELECT VERSION FROM SYSADM.PSVERSION WHERE OBJECTTYPENAME = 'CLM'), '"&DATA!C18&"', 0, ' ', 30, 0, SYSDATE, '"&CLASSDEFN_VW!$B$1&"');","")
... A331: =IF(AND(NOT(ISBLANK(DATA!A329)),DATA!A329<>DATA!A328),"INSERT INTO SYSADM.PSCLASSDEFN VALUES ('"&PSAUTHITEM_AU!$B$1 & DATA!A329&"_VW', "&"(SELECT VERSION FROM SYSADM.PSVERSION WHERE OBJECTTYPENAME = 'CLM'), '"&DATA!C329&"', 0, ' ', 30, 0, SYSDATE, '"&CLASSDEFN_VW!$B$1&"');","")
A332: =IF(AND(NOT(ISBLANK(DATA!#REF!)),DATA!#REF!<>DATA!A329),"INSERT INTO SYSADM.PSCLASSDEFN VALUES ('"&PSAUTHITEM_AU!$B$1 & DATA!#REF!&"_VW', "&"(SELECT VERSION FROM SYSADM.PSVERSION WHERE OBJECTTYPENAME = 'CLM'), '"&DATA!#REF!&"', 0, ' ', 30, 0, SYSDATE, '"&CLASSDEFN_VW!$B$1&"');","") -> #REF!
A333: =IF(AND(NOT(ISBLANK(DATA!A330)),DATA!A330<>DATA!#REF!),"INSERT INTO SYSADM.PSCLASSDEFN VALUES ('"&PSAUTHITEM_AU!$B$1 & DATA!A330&"_VW', "&"(SELECT VERSION FROM SYSADM.PSVERSION WHERE OBJECTTYPENAME = 'CLM'), '"&DATA!C330&"', 0, ' ', 30, 0, SYSDATE, '"&CLASSDEFN_VW!$B$1&"');","") -> #REF!
A334: =IF(AND(NOT(ISBLANK(DATA!A331)),DATA!A331<>DATA!A330),"INSERT INTO SYSADM.PSCLASSDEFN VALUES ('"&PSAUTHITEM_AU!$B$1 & DATA!A331&"_VW', "&"(SELECT VERSION FROM SYSADM.PSVERSION WHERE OBJECTTYPENAME = 'CLM'), '"&DATA!C331&"', 0, ' ', 30, 0, SYSDATE, '"&CLASSDEFN_VW!$B$1&"');","")
A335: =IF(AND(NOT(ISBLANK(DATA!A332)),DATA!A332<>DATA!A331),"INSERT INTO SYSADM.PSCLASSDEFN VALUES ('"&PSAUTHITEM_AU!$B$1 & DATA!A332&"_VW', "&"(SELECT VERSION FROM SYSADM.PSVERSION WHERE OBJECTTYPENAME = 'CLM'), '"&DATA!C332&"', 0, ' ', 30, 0, SYSDATE, '"&CLASSDEFN_VW!$B$1&"');","")
A336: =IF(AND(NOT(ISBLANK(DATA!A333)),DATA!A333<>DATA!A332),"INSERT INTO SYSADM.PSCLASSDEFN VALUES ('"&PSAUTHITEM_AU!$B$1 & DATA!A333&"_VW', "&"(SELECT VERSION FROM SYSADM.PSVERSION WHERE OBJECTTYPENAME = 'CLM'), '"&DATA!C333&"', 0, ' ', 30, 0, SYSDATE, '"&CLASSDEFN_VW!$B$1&"');","")
A337: =IF(AND(NOT(ISBLANK(DATA!A334)),DATA!A334<>DATA!A333),"INSERT INTO SYSADM.PSCLASSDEFN VALUES ('"&PSAUTHITEM_AU!$B$1 & DATA!A334&"_VW', "&"(SELECT VERSION FROM SYSADM.PSVERSION WHERE OBJECTTYPENAME = 'CLM'), '"&DATA!C334&"', 0, ' ', 30, 0, SYSDATE, '"&CLASSDEFN_VW!$B$1&"');","")
A338: =IF(AND(NOT(ISBLANK(DATA!A335)),DATA!A335<>DATA!A334),"INSERT INTO SYSADM.PSCLASSDEFN VALUES ('"&PSAUTHITEM_AU!$B$1 & DATA!A335&"_VW', "&"(SELECT VERSION FROM SYSADM.PSVERSION WHERE OBJECTTYPENAME = 'CLM'), '"&DATA!C335&"', 0, ' ', 30, 0, SYSDATE, '"&CLASSDEFN_VW!$B$1&"');","")
A339: =IF(AND(NOT(ISBLANK(DATA!A336)),DATA!A336<>DATA!A335),"INSERT INTO SYSADM.PSCLASSDEFN VALUES ('"&PSAUTHITEM_AU!$B$1 & DATA!A336&"_VW', "&"(SELECT VERSION FROM SYSADM.PSVERSION WHERE OBJECTTYPENAME = 'CLM'), '"&DATA!C336&"', 0, ' ', 30, 0, SYSDATE, '"&CLASSDEFN_VW!$B$1&"');","")
A340: =IF(AND(NOT(ISBLANK(DATA!A337)),DATA!A337<>DATA!A336),"INSERT INTO SYSADM.PSCLASSDEFN VALUES ('"&PSAUTHITEM_AU!$B$1 & DATA!A337&"_VW', "&"(SELECT VERSION FROM SYSADM.PSVERSION WHERE OBJECTTYPENAME = 'CLM'), '"&DATA!C337&"', 0, ' ', 30, 0, SYSDATE, '"&CLASSDEFN_VW!$B$1&"');","")
A341: =IF(AND(NOT(ISBLANK(DATA!A338)),DATA!A338<>DATA!A337),"INSERT INTO SYSADM.PSCLASSDEFN VALUES ('"&PSAUTHITEM_AU!$B$1 & DATA!A338&"_VW', "&"(SELECT VERSION FROM SYSADM.PSVERSION WHERE OBJECTTYPENAME = 'CLM'), '"&DATA!C338&"', 0, ' ', 30, 0, SYSDATE, '"&CLASSDEFN_VW!$B$1&"');","")
A342: =IF(AND(NOT(ISBLANK(DATA!A339)),DATA!A339<>DATA!A338),"INSERT INTO SYSADM.PSCLASSDEFN VALUES ('"&PSAUTHITEM_AU!$B$1 & DATA!A339&"_VW', "&"(SELECT VERSION FROM SYSADM.PSVERSION WHERE OBJECTTYPENAME = 'CLM'), '"&DATA!C339&"', 0, ' ', 30, 0, SYSDATE, '"&CLASSDEFN_VW!$B$1&"');","")
A343: =IF(AND(NOT(ISBLANK(DATA!A340)),DATA!A340<>DATA!A339),"INSERT INTO SYSADM.PSCLASSDEFN VALUES ('"&PSAUTHITEM_AU!$B$1 & DATA!A340&"_VW', "&"(SELECT VERSION FROM SYSADM.PSVERSION WHERE OBJECTTYPENAME = 'CLM'), '"&DATA!C340&"', 0, ' ', 30, 0, SYSDATE, '"&CLASSDEFN_VW!$B$1&"');","")
A344: =IF(AND(NOT(ISBLANK(DATA!A341)),DATA!A341<>DATA!A340),"INSERT INTO SYSADM.PSCLASSDEFN VALUES ('"&PSAUTHITEM_AU!$B$1 & DATA!A341&"_VW', "&"(SELECT VERSION FROM SYSADM.PSVERSION WHERE OBJECTTYPENAME = 'CLM'), '"&DATA!C341&"', 0, ' ', 30, 0, SYSDATE, '"&CLASSDEFN_VW!$B$1&"');","")
A345: =IF(AND(NOT(ISBLANK(DATA!A342)),DATA!A342<>DATA!A341),"INSERT INTO SYSADM.PSCLASSDEFN VALUES ('"&PSAUTHITEM_AU!$B$1 & DATA!A342&"_VW', "&"(SELECT VERSION FROM SYSADM.PSVERSION WHERE OBJECTTYPENAME = 'CLM'), '"&DATA!C342&"', 0, ' ', 30, 0, SYSDATE, '"&CLASSDEFN_VW!$B$1&"');","")
... A2000: =IF(AND(NOT(ISBLANK(DATA!A1997)),DATA!A1997<>DATA!A1996),"INSERT INTO SYSADM.PSCLASSDEFN VALUES ('"&PSAUTHITEM_AU!$B$1 & DATA!A1997&"_VW', "&"(SELECT VERSION FROM SYSADM.PSVERSION WHERE OBJECTTYPENAME = 'CLM'), '"&DATA!C1997&"', 0, ' ', 30, 0, SYSDATE, '"&CLASSDEFN_VW!$B$1&"');","")

Sheet CLASSDEFN_AC
A1: User | B1: =UpdateID -> 1940408
A3: SQL Statement
A4: =IF(AND(NOT(ISBLANK(DATA!A4)),DATA!A4<>DATA!A3),IF(DATA!#REF!>7,"INSERT INTO SYSADM.PSCLASSDEFN VALUES ('"&PSAUTHITEM_AU!$B$1 & DATA!A4&IF(ISEVEN(DATA!#REF!),"_C' ,","_AC', ")&"(SELECT VERSION FROM SYSADM.PSVERSION WHERE OBJECTTYPENAME = 'CLM'), '"&DATA!C4&"', 30, ' ', 0, 0, SYSDATE, '"&CLASSDEFN_AC!$B$1&"');",""),"") -> #REF!
A5: =IF(AND(NOT(ISBLANK(DATA!A5)),DATA!A5<>DATA!A4),IF(DATA!#REF!>7,"INSERT INTO SYSADM.PSCLASSDEFN VALUES ('"&PSAUTHITEM_AU!$B$1 & DATA!A5&IF(ISEVEN(DATA!#REF!),"_C' ,","_AC', ")&"(SELECT VERSION FROM SYSADM.PSVERSION WHERE OBJECTTYPENAME = 'CLM'), '"&DATA!C5&"', 30, ' ', 0, 0, SYSDATE, '"&CLASSDEFN_AC!$B$1&"');",""),"")
A6: =IF(AND(NOT(ISBLANK(DATA!#REF!)),DATA!#REF!<>DATA!A5),IF(DATA!#REF!>7,"INSERT INTO SYSADM.PSCLASSDEFN VALUES ('"&PSAUTHITEM_AU!$B$1 & DATA!#REF!&IF(ISEVEN(DATA!#REF!),"_C' ,","_AC', ")&"(SELECT VERSION FROM SYSADM.PSVERSION WHERE OBJECTTYPENAME = 'CLM'), '"&DATA!#REF!&"', 30, ' ', 0, 0, SYSDATE, '"&CLASSDEFN_AC!$B$1&"');",""),"") -> #REF!
A7: =IF(AND(NOT(ISBLANK(DATA!#REF!)),DATA!#REF!<>DATA!#REF!),IF(DATA!#REF!>7,"INSERT INTO SYSADM.PSCLASSDEFN VALUES ('"&PSAUTHITEM_AU!$B$1 & DATA!#REF!&IF(ISEVEN(DATA!#REF!),"_C' ,","_AC', ")&"(SELECT VERSION FROM SYSADM.PSVERSION WHERE OBJECTTYPENAME = 'CLM'), '"&DATA!#REF!&"', 30, ' ', 0, 0, SYSDATE, '"&CLASSDEFN_AC!$B$1&"');",""),"") -> #REF!
A8: =IF(AND(NOT(ISBLANK(DATA!A6)),DATA!A6<>DATA!#REF!),IF(DATA!#REF!>7,"INSERT INTO SYSADM.PSCLASSDEFN VALUES ('"&PSAUTHITEM_AU!$B$1 & DATA!A6&IF(ISEVEN(DATA!#REF!),"_C' ,","_AC', ")&"(SELECT VERSION FROM SYSADM.PSVERSION WHERE OBJECTTYPENAME = 'CLM'), '"&DATA!C6&"', 30, ' ', 0, 0, SYSDATE, '"&CLASSDEFN_AC!$B$1&"');",""),"") -> #REF!
A9: =IF(AND(NOT(ISBLANK(DATA!A7)),DATA!A7<>DATA!A6),IF(DATA!#REF!>7,"INSERT INTO SYSADM.PSCLASSDEFN VALUES ('"&PSAUTHITEM_AU!$B$1 & DATA!A7&IF(ISEVEN(DATA!#REF!),"_C' ,","_AC', ")&"(SELECT VERSION FROM SYSADM.PSVERSION WHERE OBJECTTYPENAME = 'CLM'), '"&DATA!C7&"', 30, ' ', 0, 0, SYSDATE, '"&CLASSDEFN_AC!$B$1&"');",""),"")
A10: =IF(AND(NOT(ISBLANK(DATA!A8)),DATA!A8<>DATA!A7),IF(DATA!#REF!>7,"INSERT INTO SYSADM.PSCLASSDEFN VALUES ('"&PSAUTHITEM_AU!$B$1 & DATA!A8&IF(ISEVEN(DATA!#REF!),"_C' ,","_AC', ")&"(SELECT VERSION FROM SYSADM.PSVERSION WHERE OBJECTTYPENAME = 'CLM'), '"&DATA!C8&"', 30, ' ', 0, 0, SYSDATE, '"&CLASSDEFN_AC!$B$1&"');",""),"")
A11: =IF(AND(NOT(ISBLANK(DATA!A9)),DATA!A9<>DATA!A8),IF(DATA!#REF!>7,"INSERT INTO SYSADM.PSCLASSDEFN VALUES ('"&PSAUTHITEM_AU!$B$1 & DATA!A9&IF(ISEVEN(DATA!#REF!),"_C' ,","_AC', ")&"(SELECT VERSION FROM SYSADM.PSVERSION WHERE OBJECTTYPENAME = 'CLM'), '"&DATA!C9&"', 30, ' ', 0, 0, SYSDATE, '"&CLASSDEFN_AC!$B$1&"');",""),"")
A12: =IF(AND(NOT(ISBLANK(DATA!A10)),DATA!A10<>DATA!A9),IF(DATA!#REF!>7,"INSERT INTO SYSADM.PSCLASSDEFN VALUES ('"&PSAUTHITEM_AU!$B$1 & DATA!A10&IF(ISEVEN(DATA!#REF!),"_C' ,","_AC', ")&"(SELECT VERSION FROM SYSADM.PSVERSION WHERE OBJECTTYPENAME = 'CLM'), '"&DATA!C10&"', 30, ' ', 0, 0, SYSDATE, '"&CLASSDEFN_AC!$B$1&"');",""),"")
A13: =IF(AND(NOT(ISBLANK(DATA!A11)),DATA!A11<>DATA!A10),IF(DATA!#REF!>7,"INSERT INTO SYSADM.PSCLASSDEFN VALUES ('"&PSAUTHITEM_AU!$B$1 & DATA!A11&IF(ISEVEN(DATA!#REF!),"_C' ,","_AC', ")&"(SELECT VERSION FROM SYSADM.PSVERSION WHERE OBJECTTYPENAME = 'CLM'), '"&DATA!C11&"', 30, ' ', 0, 0, SYSDATE, '"&CLASSDEFN_AC!$B$1&"');",""),"")
A14: =IF(AND(NOT(ISBLANK(DATA!A12)),DATA!A12<>DATA!A11),IF(DATA!#REF!>7,"INSERT INTO SYSADM.PSCLASSDEFN VALUES ('"&PSAUTHITEM_AU!$B$1 & DATA!A12&IF(ISEVEN(DATA!#REF!),"_C' ,","_AC', ")&"(SELECT VERSION FROM SYSADM.PSVERSION WHERE OBJECTTYPENAME = 'CLM'), '"&DATA!C12&"', 30, ' ', 0, 0, SYSDATE, '"&CLASSDEFN_AC!$B$1&"');",""),"")
A15: =IF(AND(NOT(ISBLANK(DATA!A13)),DATA!A13<>DATA!A12),IF(DATA!#REF!>7,"INSERT INTO SYSADM.PSCLASSDEFN VALUES ('"&PSAUTHITEM_AU!$B$1 & DATA!A13&IF(ISEVEN(DATA!#REF!),"_C' ,","_AC', ")&"(SELECT VERSION FROM SYSADM.PSVERSION WHERE OBJECTTYPENAME = 'CLM'), '"&DATA!C13&"', 30, ' ', 0, 0, SYSDATE, '"&CLASSDEFN_AC!$B$1&"');",""),"")
A16: =IF(AND(NOT(ISBLANK(DATA!A14)),DATA!A14<>DATA!A13),IF(DATA!#REF!>7,"INSERT INTO SYSADM.PSCLASSDEFN VALUES ('"&PSAUTHITEM_AU!$B$1 & DATA!A14&IF(ISEVEN(DATA!#REF!),"_C' ,","_AC', ")&"(SELECT VERSION FROM SYSADM.PSVERSION WHERE OBJECTTYPENAME = 'CLM'), '"&DATA!C14&"', 30, ' ', 0, 0, SYSDATE, '"&CLASSDEFN_AC!$B$1&"');",""),"")
A17: =IF(AND(NOT(ISBLANK(DATA!A15)),DATA!A15<>DATA!A14),IF(DATA!#REF!>7,"INSERT INTO SYSADM.PSCLASSDEFN VALUES ('"&PSAUTHITEM_AU!$B$1 & DATA!A15&IF(ISEVEN(DATA!#REF!),"_C' ,","_AC', ")&"(SELECT VERSION FROM SYSADM.PSVERSION WHERE OBJECTTYPENAME = 'CLM'), '"&DATA!C15&"', 30, ' ', 0, 0, SYSDATE, '"&CLASSDEFN_AC!$B$1&"');",""),"")
A18: =IF(AND(NOT(ISBLANK(DATA!A16)),DATA!A16<>DATA!A15),IF(DATA!#REF!>7,"INSERT INTO SYSADM.PSCLASSDEFN VALUES ('"&PSAUTHITEM_AU!$B$1 & DATA!A16&IF(ISEVEN(DATA!#REF!),"_C' ,","_AC', ")&"(SELECT VERSION FROM SYSADM.PSVERSION WHERE OBJECTTYPENAME = 'CLM'), '"&DATA!C16&"', 30, ' ', 0, 0, SYSDATE, '"&CLASSDEFN_AC!$B$1&"');",""),"")
A19: =IF(AND(NOT(ISBLANK(DATA!A17)),DATA!A17<>DATA!A16),IF(DATA!#REF!>7,"INSERT INTO SYSADM.PSCLASSDEFN VALUES ('"&PSAUTHITEM_AU!$B$1 & DATA!A17&IF(ISEVEN(DATA!#REF!),"_C' ,","_AC', ")&"(SELECT VERSION FROM SYSADM.PSVERSION WHERE OBJECTTYPENAME = 'CLM'), '"&DATA!C17&"', 30, ' ', 0, 0, SYSDATE, '"&CLASSDEFN_AC!$B$1&"');",""),"")
A20: =IF(AND(NOT(ISBLANK(DATA!A18)),DATA!A18<>DATA!A17),IF(DATA!#REF!>7,"INSERT INTO SYSADM.PSCLASSDEFN VALUES ('"&PSAUTHITEM_AU!$B$1 & DATA!A18&IF(ISEVEN(DATA!#REF!),"_C' ,","_AC', ")&"(SELECT VERSION FROM SYSADM.PSVERSION WHERE OBJECTTYPENAME = 'CLM'), '"&DATA!C18&"', 30, ' ', 0, 0, SYSDATE, '"&CLASSDEFN_AC!$B$1&"');",""),"")
... A24: =IF(AND(NOT(ISBLANK(DATA!A22)),DATA!A22<>DATA!A21),IF(DATA!#REF!>7,"INSERT INTO SYSADM.PSCLASSDEFN VALUES ('"&PSAUTHITEM_AU!$B$1 & DATA!A22&IF(ISEVEN(DATA!#REF!),"_C' ,","_AC', ")&"(SELECT VERSION FROM SYSADM.PSVERSION WHERE OBJECTTYPENAME = 'CLM'), '"&DATA!C22&"', 30, ' ', 0, 0, SYSDATE, '"&CLASSDEFN_AC!$B$1&"');",""),"")
A25: =IF(AND(NOT(ISBLANK(DATA!A23)),DATA!A23<>DATA!A22),IF(DATA!I4>7,"INSERT INTO SYSADM.PSCLASSDEFN VALUES ('"&PSAUTHITEM_AU!$B$1 & DATA!A23&IF(ISEVEN(DATA!J4),"_C' ,","_AC', ")&"(SELECT VERSION FROM SYSADM.PSVERSION WHERE OBJECTTYPENAME = 'CLM'), '"&DATA!C23&"', 30, ' ', 0, 0, SYSDATE, '"&CLASSDEFN_AC!$B$1&"');",""),"")
A26: =IF(AND(NOT(ISBLANK(DATA!A24)),DATA!A24<>DATA!A23),IF(DATA!I5>7,"INSERT INTO SYSADM.PSCLASSDEFN VALUES ('"&PSAUTHITEM_AU!$B$1 & DATA!A24&IF(ISEVEN(DATA!J5),"_C' ,","_AC', ")&"(SELECT VERSION FROM SYSADM.PSVERSION WHERE OBJECTTYPENAME = 'CLM'), '"&DATA!C24&"', 30, ' ', 0, 0, SYSDATE, '"&CLASSDEFN_AC!$B$1&"');",""),"")
A27: =IF(AND(NOT(ISBLANK(DATA!A25)),DATA!A25<>DATA!A24),IF(DATA!I6>7,"INSERT INTO SYSADM.PSCLASSDEFN VALUES ('"&PSAUTHITEM_AU!$B$1 & DATA!A25&IF(ISEVEN(DATA!J6),"_C' ,","_AC', ")&"(SELECT VERSION FROM SYSADM.PSVERSION WHERE OBJECTTYPENAME = 'CLM'), '"&DATA!C25&"', 30, ' ', 0, 0, SYSDATE, '"&CLASSDEFN_AC!$B$1&"');",""),"")
A28: =IF(AND(NOT(ISBLANK(DATA!A26)),DATA!A26<>DATA!A25),IF(DATA!I7>7,"INSERT INTO SYSADM.PSCLASSDEFN VALUES ('"&PSAUTHITEM_AU!$B$1 & DATA!A26&IF(ISEVEN(DATA!J7),"_C' ,","_AC', ")&"(SELECT VERSION FROM SYSADM.PSVERSION WHERE OBJECTTYPENAME = 'CLM'), '"&DATA!C26&"', 30, ' ', 0, 0, SYSDATE, '"&CLASSDEFN_AC!$B$1&"');",""),"")
A29: =IF(AND(NOT(ISBLANK(DATA!A27)),DATA!A27<>DATA!A26),IF(DATA!I8>7,"INSERT INTO SYSADM.PSCLASSDEFN VALUES ('"&PSAUTHITEM_AU!$B$1 & DATA!A27&IF(ISEVEN(DATA!J8),"_C' ,","_AC', ")&"(SELECT VERSION FROM SYSADM.PSVERSION WHERE OBJECTTYPENAME = 'CLM'), '"&DATA!C27&"', 30, ' ', 0, 0, SYSDATE, '"&CLASSDEFN_AC!$B$1&"');",""),"")
A30: =IF(AND(NOT(ISBLANK(DATA!A28)),DATA!A28<>DATA!A27),IF(DATA!I9>7,"INSERT INTO SYSADM.PSCLASSDEFN VALUES ('"&PSAUTHITEM_AU!$B$1 & DATA!A28&IF(ISEVEN(DATA!J9),"_C' ,","_AC', ")&"(SELECT VERSION FROM SYSADM.PSVERSION WHERE OBJECTTYPENAME = 'CLM'), '"&DATA!C28&"', 30, ' ', 0, 0, SYSDATE, '"&CLASSDEFN_AC!$B$1&"');",""),"")
A31: =IF(AND(NOT(ISBLANK(DATA!A29)),DATA!A29<>DATA!A28),IF(DATA!I10>7,"INSERT INTO SYSADM.PSCLASSDEFN VALUES ('"&PSAUTHITEM_AU!$B$1 & DATA!A29&IF(ISEVEN(DATA!J10),"_C' ,","_AC', ")&"(SELECT VERSION FROM SYSADM.PSVERSION WHERE OBJECTTYPENAME = 'CLM'), '"&DATA!C29&"', 30, ' ', 0, 0, SYSDATE, '"&CLASSDEFN_AC!$B$1&"');",""),"")
A32: =IF(AND(NOT(ISBLANK(DATA!A30)),DATA!A30<>DATA!A29),IF(DATA!I11>7,"INSERT INTO SYSADM.PSCLASSDEFN VALUES ('"&PSAUTHITEM_AU!$B$1 & DATA!A30&IF(ISEVEN(DATA!J11),"_C' ,","_AC', ")&"(SELECT VERSION FROM SYSADM.PSVERSION WHERE OBJECTTYPENAME = 'CLM'), '"&DATA!C30&"', 30, ' ', 0, 0, SYSDATE, '"&CLASSDEFN_AC!$B$1&"');",""),"")
A33: =IF(AND(NOT(ISBLANK(DATA!A31)),DATA!A31<>DATA!A30),IF(DATA!I12>7,"INSERT INTO SYSADM.PSCLASSDEFN VALUES ('"&PSAUTHITEM_AU!$B$1 & DATA!A31&IF(ISEVEN(DATA!J12),"_C' ,","_AC', ")&"(SELECT VERSION FROM SYSADM.PSVERSION WHERE OBJECTTYPENAME = 'CLM'), '"&DATA!C31&"', 30, ' ', 0, 0, SYSDATE, '"&CLASSDEFN_AC!$B$1&"');",""),"")
A34: =IF(AND(NOT(ISBLANK(DATA!A32)),DATA!A32<>DATA!A31),IF(DATA!I13>7,"INSERT INTO SYSADM.PSCLASSDEFN VALUES ('"&PSAUTHITEM_AU!$B$1 & DATA!A32&IF(ISEVEN(DATA!J13),"_C' ,","_AC', ")&"(SELECT VERSION FROM SYSADM.PSVERSION WHERE OBJECTTYPENAME = 'CLM'), '"&DATA!C32&"', 30, ' ', 0, 0, SYSDATE, '"&CLASSDEFN_AC!$B$1&"');",""),"")
A35: =IF(AND(NOT(ISBLANK(DATA!A33)),DATA!A33<>DATA!A32),IF(DATA!I14>7,"INSERT INTO SYSADM.PSCLASSDEFN VALUES ('"&PSAUTHITEM_AU!$B$1 & DATA!A33&IF(ISEVEN(DATA!J14),"_C' ,","_AC', ")&"(SELECT VERSION FROM SYSADM.PSVERSION WHERE OBJECTTYPENAME = 'CLM'), '"&DATA!C33&"', 30, ' ', 0, 0, SYSDATE, '"&CLASSDEFN_AC!$B$1&"');",""),"")
A36: =IF(AND(NOT(ISBLANK(DATA!A34)),DATA!A34<>DATA!A33),IF(DATA!I15>7,"INSERT INTO SYSADM.PSCLASSDEFN VALUES ('"&PSAUTHITEM_AU!$B$1 & DATA!A34&IF(ISEVEN(DATA!J15),"_C' ,","_AC', ")&"(SELECT VERSION FROM SYSADM.PSVERSION WHERE OBJECTTYPENAME = 'CLM'), '"&DATA!C34&"', 30, ' ', 0, 0, SYSDATE, '"&CLASSDEFN_AC!$B$1&"');",""),"")
... A331: =IF(AND(NOT(ISBLANK(DATA!A329)),DATA!A329<>DATA!A328),IF(DATA!I310>7,"INSERT INTO SYSADM.PSCLASSDEFN VALUES ('"&PSAUTHITEM_AU!$B$1 & DATA!A329&IF(ISEVEN(DATA!J310),"_C' ,","_AC', ")&"(SELECT VERSION FROM SYSADM.PSVERSION WHERE OBJECTTYPENAME = 'CLM'), '"&DATA!C329&"', 30, ' ', 0, 0, SYSDATE, '"&CLASSDEFN_AC!$B$1&"');",""),"")
A332: =IF(AND(NOT(ISBLANK(DATA!#REF!)),DATA!#REF!<>DATA!A329),IF(DATA!#REF!>7,"INSERT INTO SYSADM.PSCLASSDEFN VALUES ('"&PSAUTHITEM_AU!$B$1 & DATA!#REF!&IF(ISEVEN(DATA!#REF!),"_C' ,","_AC', ")&"(SELECT VERSION FROM SYSADM.PSVERSION WHERE OBJECTTYPENAME = 'CLM'), '"&DATA!#REF!&"', 30, ' ', 0, 0, SYSDATE, '"&CLASSDEFN_AC!$B$1&"');",""),"") -> #REF!
A333: =IF(AND(NOT(ISBLANK(DATA!A330)),DATA!A330<>DATA!#REF!),IF(DATA!I311>7,"INSERT INTO SYSADM.PSCLASSDEFN VALUES ('"&PSAUTHITEM_AU!$B$1 & DATA!A330&IF(ISEVEN(DATA!J311),"_C' ,","_AC', ")&"(SELECT VERSION FROM SYSADM.PSVERSION WHERE OBJECTTYPENAME = 'CLM'), '"&DATA!C330&"', 30, ' ', 0, 0, SYSDATE, '"&CLASSDEFN_AC!$B$1&"');",""),"") -> #REF!
A334: =IF(AND(NOT(ISBLANK(DATA!A331)),DATA!A331<>DATA!A330),IF(DATA!I312>7,"INSERT INTO SYSADM.PSCLASSDEFN VALUES ('"&PSAUTHITEM_AU!$B$1 & DATA!A331&IF(ISEVEN(DATA!J312),"_C' ,","_AC', ")&"(SELECT VERSION FROM SYSADM.PSVERSION WHERE OBJECTTYPENAME = 'CLM'), '"&DATA!C331&"', 30, ' ', 0, 0, SYSDATE, '"&CLASSDEFN_AC!$B$1&"');",""),"")
A335: =IF(AND(NOT(ISBLANK(DATA!A332)),DATA!A332<>DATA!A331),IF(DATA!I313>7,"INSERT INTO SYSADM.PSCLASSDEFN VALUES ('"&PSAUTHITEM_AU!$B$1 & DATA!A332&IF(ISEVEN(DATA!J313),"_C' ,","_AC', ")&"(SELECT VERSION FROM SYSADM.PSVERSION WHERE OBJECTTYPENAME = 'CLM'), '"&DATA!C332&"', 30, ' ', 0, 0, SYSDATE, '"&CLASSDEFN_AC!$B$1&"');",""),"")
A336: =IF(AND(NOT(ISBLANK(DATA!A333)),DATA!A333<>DATA!A332),IF(DATA!I314>7,"INSERT INTO SYSADM.PSCLASSDEFN VALUES ('"&PSAUTHITEM_AU!$B$1 & DATA!A333&IF(ISEVEN(DATA!J314),"_C' ,","_AC', ")&"(SELECT VERSION FROM SYSADM.PSVERSION WHERE OBJECTTYPENAME = 'CLM'), '"&DATA!C333&"', 30, ' ', 0, 0, SYSDATE, '"&CLASSDEFN_AC!$B$1&"');",""),"")
A337: =IF(AND(NOT(ISBLANK(DATA!A334)),DATA!A334<>DATA!A333),IF(DATA!I315>7,"INSERT INTO SYSADM.PSCLASSDEFN VALUES ('"&PSAUTHITEM_AU!$B$1 & DATA!A334&IF(ISEVEN(DATA!J315),"_C' ,","_AC', ")&"(SELECT VERSION FROM SYSADM.PSVERSION WHERE OBJECTTYPENAME = 'CLM'), '"&DATA!C334&"', 30, ' ', 0, 0, SYSDATE, '"&CLASSDEFN_AC!$B$1&"');",""),"")
A338: =IF(AND(NOT(ISBLANK(DATA!A335)),DATA!A335<>DATA!A334),IF(DATA!I316>7,"INSERT INTO SYSADM.PSCLASSDEFN VALUES ('"&PSAUTHITEM_AU!$B$1 & DATA!A335&IF(ISEVEN(DATA!J316),"_C' ,","_AC', ")&"(SELECT VERSION FROM SYSADM.PSVERSION WHERE OBJECTTYPENAME = 'CLM'), '"&DATA!C335&"', 30, ' ', 0, 0, SYSDATE, '"&CLASSDEFN_AC!$B$1&"');",""),"")
...

Sheet PSAUTHITEM_VW
A1: Prefix: | B1: =Prefix -> UCCS_UXDSP_
A3: SQL Statement
A4: =IF(NOT(ISBLANK(DATA!A4)),"INSERT INTO SYSADM.PSAUTHITEM VALUES ('"&$B$1&DATA!A4&"_VW', '"&DATA!#REF!&"', '"&DATA!#REF!&"', '"&DATA!#REF!&"', '"&DATA!#REF!&"', 1, "&DATA!K4&");","") -> #REF!
A5: =IF(NOT(ISBLANK(DATA!A5)),"INSERT INTO SYSADM.PSAUTHITEM VALUES ('"&$B$1&DATA!A5&"_VW', '"&DATA!#REF!&"', '"&DATA!#REF!&"', '"&DATA!#REF!&"', '"&DATA!#REF!&"', 1, "&DATA!K5&");","") -> #REF!
A6: =IF(NOT(ISBLANK(DATA!#REF!)),"INSERT INTO SYSADM.PSAUTHITEM VALUES ('"&$B$1&DATA!#REF!&"_VW', '"&DATA!#REF!&"', '"&DATA!#REF!&"', '"&DATA!#REF!&"', '"&DATA!#REF!&"', 1, "&DATA!K6&");","") -> #REF!
A7: =IF(NOT(ISBLANK(DATA!#REF!)),"INSERT INTO SYSADM.PSAUTHITEM VALUES ('"&$B$1&DATA!#REF!&"_VW', '"&DATA!#REF!&"', '"&DATA!#REF!&"', '"&DATA!#REF!&"', '"&DATA!#REF!&"', 1, "&DATA!K7&");","") -> #REF!
A8: =IF(NOT(ISBLANK(DATA!A6)),"INSERT INTO SYSADM.PSAUTHITEM VALUES ('"&$B$1&DATA!A6&"_VW', '"&DATA!#REF!&"', '"&DATA!#REF!&"', '"&DATA!#REF!&"', '"&DATA!#REF!&"', 1, "&DATA!K8&");","") -> #REF!
A9: =IF(NOT(ISBLANK(DATA!A7)),"INSERT INTO SYSADM.PSAUTHITEM VALUES ('"&$B$1&DATA!A7&"_VW', '"&DATA!#REF!&"', '"&DATA!#REF!&"', '"&DATA!#REF!&"', '"&DATA!#REF!&"', 1, "&DATA!K9&");","") -> #REF!
A10: =IF(NOT(ISBLANK(DATA!A8)),"INSERT INTO SYSADM.PSAUTHITEM VALUES ('"&$B$1&DATA!A8&"_VW', '"&DATA!#REF!&"', '"&DATA!#REF!&"', '"&DATA!#REF!&"', '"&DATA!#REF!&"', 1, "&DATA!K10&");","") -> #REF!
A11: =IF(NOT(ISBLANK(DATA!A9)),"INSERT INTO SYSADM.PSAUTHITEM VALUES ('"&$B$1&DATA!A9&"_VW', '"&DATA!#REF!&"', '"&DATA!#REF!&"', '"&DATA!#REF!&"', '"&DATA!#REF!&"', 1, "&DATA!K11&");","") -> #REF!
A12: =IF(NOT(ISBLANK(DATA!A10)),"INSERT INTO SYSADM.PSAUTHITEM VALUES ('"&$B$1&DATA!A10&"_VW', '"&DATA!#REF!&"', '"&DATA!#REF!&"', '"&DATA!#REF!&"', '"&DATA!#REF!&"', 1, "&DATA!K12&");","") -> #REF!
A13: =IF(NOT(ISBLANK(DATA!A11)),"INSERT INTO SYSADM.PSAUTHITEM VALUES ('"&$B$1&DATA!A11&"_VW', '"&DATA!#REF!&"', '"&DATA!#REF!&"', '"&DATA!#REF!&"', '"&DATA!#REF!&"', 1, "&DATA!K13&");","") -> #REF!
A14: =IF(NOT(ISBLANK(DATA!A12)),"INSERT INTO SYSADM.PSAUTHITEM VALUES ('"&$B$1&DATA!A12&"_VW', '"&DATA!#REF!&"', '"&DATA!#REF!&"', '"&DATA!#REF!&"', '"&DATA!#REF!&"', 1, "&DATA!K14&");","") -> #REF!
A15: =IF(NOT(ISBLANK(DATA!A13)),"INSERT INTO SYSADM.PSAUTHITEM VALUES ('"&$B$1&DATA!A13&"_VW', '"&DATA!#REF!&"', '"&DATA!#REF!&"', '"&DATA!#REF!&"', '"&DATA!#REF!&"', 1, "&DATA!K15&");","") -> #REF!
A16: =IF(NOT(ISBLANK(DATA!A14)),"INSERT INTO SYSADM.PSAUTHITEM VALUES ('"&$B$1&DATA!A14&"_VW', '"&DATA!#REF!&"', '"&DATA!#REF!&"', '"&DATA!#REF!&"', '"&DATA!#REF!&"', 1, "&DATA!K16&");","") -> #REF!
A17: =IF(NOT(ISBLANK(DATA!A15)),"INSERT INTO SYSADM.PSAUTHITEM VALUES ('"&$B$1&DATA!A15&"_VW', '"&DATA!#REF!&"', '"&DATA!#REF!&"', '"&DATA!#REF!&"', '"&DATA!#REF!&"', 1, "&DATA!K17&");","") -> #REF!
A18: =IF(NOT(ISBLANK(DATA!A16)),"INSERT INTO SYSADM.PSAUTHITEM VALUES ('"&$B$1&DATA!A16&"_VW', '"&DATA!#REF!&"', '"&DATA!#REF!&"', '"&DATA!#REF!&"', '"&DATA!#REF!&"', 1, "&DATA!K18&");","") -> #REF!
A19: =IF(NOT(ISBLANK(DATA!A17)),"INSERT INTO SYSADM.PSAUTHITEM VALUES ('"&$B$1&DATA!A17&"_VW', '"&DATA!#REF!&"', '"&DATA!#REF!&"', '"&DATA!#REF!&"', '"&DATA!#REF!&"', 1, "&DATA!K19&");","") -> #REF!
... A24: =IF(NOT(ISBLANK(DATA!A22)),"INSERT INTO SYSADM.PSAUTHITEM VALUES ('"&$B$1&DATA!A22&"_VW', '"&DATA!#REF!&"', '"&DATA!#REF!&"', '"&DATA!#REF!&"', '"&DATA!#REF!&"', 1, "&DATA!K24&");","") -> #REF!
A25: =IF(NOT(ISBLANK(DATA!A23)),"INSERT INTO SYSADM.PSAUTHITEM VALUES ('"&$B$1&DATA!A23&"_VW', '"&DATA!D4&"', '"&DATA!E4&"', '"&DATA!F4&"', '"&DATA!G4&"', 1, "&DATA!K25&");","") -> INSERT INTO SYSADM.PSAUTHITEM VALUES ('UCCS_UXDSP_STDNT_DISBLTY_SUPV2_VW', 'CALCULATE_TUITION_AND_FEES', 'INQUIRE', 'FEES_AFTER_CALCULATION', 'FEES_AFTER_CALCULATION', 1, );
A26: =IF(NOT(ISBLANK(DATA!A24)),"INSERT INTO SYSADM.PSAUTHITEM VALUES ('"&$B$1&DATA!A24&"_VW', '"&DATA!D5&"', '"&DATA!E5&"', '"&DATA!F5&"', '"&DATA!G5&"', 1, "&DATA!K26&");","") -> INSERT INTO SYSADM.PSAUTHITEM VALUES ('UCCS_UXDSP_STDNT_DISBLTY_SUPV2_VW', 'CALCULATE_TUITION_AND_FEES', 'USE', 'STDNT_EQUTN_VARS', 'STDNT_EQUTIN_CHAR', 1, );
A27: =IF(NOT(ISBLANK(DATA!A25)),"INSERT INTO SYSADM.PSAUTHITEM VALUES ('"&$B$1&DATA!A25&"_VW', '"&DATA!D6&"', '"&DATA!E6&"', '"&DATA!F6&"', '"&DATA!G6&"', 1, "&DATA!K27&");","") -> INSERT INTO SYSADM.PSAUTHITEM VALUES ('UCCS_UXDSP_STDNT_DISBLTY_SUPV2_VW', 'CALCULATE_TUITION_AND_FEES', 'USE', 'STDNT_EQUTN_VARS', 'STDNT_EQUTN_FLAG', 1, );
A28: =IF(NOT(ISBLANK(DATA!A26)),"INSERT INTO SYSADM.PSAUTHITEM VALUES ('"&$B$1&DATA!A26&"_VW', '"&DATA!D7&"', '"&DATA!E7&"', '"&DATA!F7&"', '"&DATA!G7&"', 1, "&DATA!K28&");","") -> INSERT INTO SYSADM.PSAUTHITEM VALUES ('UCCS_UXDSP_STDNT_DISBLTY_SUPV2_VW', 'CALCULATE_TUITION_AND_FEES', 'USE', 'STDNT_EQUTN_VARS', 'STDNT_EQUTN_NUM', 1, );
A29: =IF(NOT(ISBLANK(DATA!A27)),"INSERT INTO SYSADM.PSAUTHITEM VALUES ('"&$B$1&DATA!A27&"_VW', '"&DATA!D8&"', '"&DATA!E8&"', '"&DATA!F8&"', '"&DATA!G8&"', 1, "&DATA!K29&");","") -> INSERT INTO SYSADM.PSAUTHITEM VALUES ('UCCS_UXDSP_STDNT_DISBLTY_SUPV2_VW', 'CALCULATE_TUITION_AND_FEES', 'USE', 'TUITION_CALC', 'STDNT_TUITION_CALC', 1, );
A30: =IF(NOT(ISBLANK(DATA!A28)),"INSERT INTO SYSADM.PSAUTHITEM VALUES ('"&$B$1&DATA!A28&"_VW', '"&DATA!D9&"', '"&DATA!E9&"', '"&DATA!F9&"', '"&DATA!G9&"', 1, "&DATA!K30&");","") -> INSERT INTO SYSADM.PSAUTHITEM VALUES ('UCCS_UXDSP_STDNT_DISBLTY_SUPV2_VW', 'CC_BIO_DEMO_DATA_STDNT', 'INQUIRE', 'SCC_ADDR_PERS_INQ', 'SCC_ADDR_PERS_INQ', 1, );
A31: =IF(NOT(ISBLANK(DATA!A29)),"INSERT INTO SYSADM.PSAUTHITEM VALUES ('"&$B$1&DATA!A29&"_VW', '"&DATA!D10&"', '"&DATA!E10&"', '"&DATA!F10&"', '"&DATA!G10&"', 1, "&DATA!K31&");","") -> INSERT INTO SYSADM.PSAUTHITEM VALUES ('UCCS_UXDSP_STDNT_DISBLTY_SUPV2_VW', 'CC_BIO_DEMO_DATA_STDNT', 'INQUIRE', 'SCC_EADDR_PERS_INQ', 'SCC_EADDR_PERS_INQ', 1, );
A32: =IF(NOT(ISBLANK(DATA!A30)),"INSERT INTO SYSADM.PSAUTHITEM VALUES ('"&$B$1&DATA!A30&"_VW', '"&DATA!D11&"', '"&DATA!E11&"', '"&DATA!F11&"', '"&DATA!G11&"', 1, "&DATA!K32&");","") -> INSERT INTO SYSADM.PSAUTHITEM VALUES ('UCCS_UXDSP_STDNT_DISBLTY_SUPV2_VW', 'CC_BIO_DEMO_DATA_STDNT', 'INQUIRE', 'SCC_NAMES_INQ', 'SCC_NAMES_INQ', 1, );
A33: =IF(NOT(ISBLANK(DATA!A31)),"INSERT INTO SYSADM.PSAUTHITEM VALUES ('"&$B$1&DATA!A31&"_VW', '"&DATA!D12&"', '"&DATA!E12&"', '"&DATA!F12&"', '"&DATA!G12&"', 1, "&DATA!K33&");","") -> INSERT INTO SYSADM.PSAUTHITEM VALUES ('UCCS_UXDSP_STDNT_DISBLTY_SUPV2_VW', 'CC_BIO_DEMO_DATA_STDNT', 'INQUIRE', 'SCC_PHONE_PERS_INQ', 'SCC_PHONE_PERS_INQ', 1, );
A34: =IF(NOT(ISBLANK(DATA!A32)),"INSERT INTO SYSADM.PSAUTHITEM VALUES ('"&$B$1&DATA!A32&"_VW', '"&DATA!D13&"', '"&DATA!E13&"', '"&DATA!F13&"', '"&DATA!G13&"', 1, "&DATA!K34&");","") -> INSERT INTO SYSADM.PSAUTHITEM VALUES ('UCCS_UXDSP_STDNT_DISBLTY_SUPV2_VW', 'CC_BIO_DEMO_DATA_STDNT', 'USE', 'EMERGENCY_CONTACTS', 'SCC_EMERG_CNTCT1', 1, );
A35: =IF(NOT(ISBLANK(DATA!A33)),"INSERT INTO SYSADM.PSAUTHITEM VALUES ('"&$B$1&DATA!A33&"_VW', '"&DATA!D14&"', '"&DATA!E14&"', '"&DATA!F14&"', '"&DATA!G14&"', 1, "&DATA!K35&");","") -> INSERT INTO SYSADM.PSAUTHITEM VALUES ('UCCS_UXDSP_STDNT_DISBLTY_SUPV2_VW', 'CC_BIO_DEMO_DATA_STDNT', 'USE', 'EMERGENCY_CONTACTS', 'SCC_EMERG_CNTCT2', 1, );
A36: =IF(NOT(ISBLANK(DATA!A34)),"INSERT INTO SYSADM.PSAUTHITEM VALUES ('"&$B$1&DATA!A34&"_VW', '"&DATA!D15&"', '"&DATA!E15&"', '"&DATA!F15&"', '"&DATA!G15&"', 1, "&DATA!K36&");","") -> INSERT INTO SYSADM.PSAUTHITEM VALUES ('UCCS_UXDSP_STDNT_DISBLTY_SUPV2_VW', 'CC_BIO_DEMO_DATA_STDNT', 'USE', 'ETHNICITY_DETAIL', 'ETHNICITY_DETAIL', 1, );
... A331: =IF(NOT(ISBLANK(DATA!A329)),"INSERT INTO SYSADM.PSAUTHITEM VALUES ('"&$B$1&DATA!A329&"_VW', '"&DATA!D310&"', '"&DATA!E310&"', '"&DATA!F310&"', '"&DATA!G310&"', 1, "&DATA!K331&");","")
A332: =IF(NOT(ISBLANK(DATA!#REF!)),"INSERT INTO SYSADM.PSAUTHITEM VALUES ('"&$B$1&DATA!#REF!&"_VW', '"&DATA!#REF!&"', '"&DATA!#REF!&"', '"&DATA!#REF!&"', '"&DATA!#REF!&"', 1, "&DATA!#REF!&");","") -> #REF!
A333: =IF(NOT(ISBLANK(DATA!A330)),"INSERT INTO SYSADM.PSAUTHITEM VALUES ('"&$B$1&DATA!A330&"_VW', '"&DATA!D311&"', '"&DATA!E311&"', '"&DATA!F311&"', '"&DATA!G311&"', 1, "&DATA!K332&");","")
A334: =IF(NOT(ISBLANK(DATA!A331)),"INSERT INTO SYSADM.PSAUTHITEM VALUES ('"&$B$1&DATA!A331&"_VW', '"&DATA!D312&"', '"&DATA!E312&"', '"&DATA!F312&"', '"&DATA!G312&"', 1, "&DATA!K333&");","")
A335: =IF(NOT(ISBLANK(DATA!A332)),"INSERT INTO SYSADM.PSAUTHITEM VALUES ('"&$B$1&DATA!A332&"_VW', '"&DATA!D313&"', '"&DATA!E313&"', '"&DATA!F313&"', '"&DATA!G313&"', 1, "&DATA!K334&");","")
A336: =IF(NOT(ISBLANK(DATA!A333)),"INSERT INTO SYSADM.PSAUTHITEM VALUES ('"&$B$1&DATA!A333&"_VW', '"&DATA!D314&"', '"&DATA!E314&"', '"&DATA!F314&"', '"&DATA!G314&"', 1, "&DATA!K335&");","")
A337: =IF(NOT(ISBLANK(DATA!A334)),"INSERT INTO SYSADM.PSAUTHITEM VALUES ('"&$B$1&DATA!A334&"_VW', '"&DATA!D315&"', '"&DATA!E315&"', '"&DATA!F315&"', '"&DATA!G315&"', 1, "&DATA!K336&");","")
A338: =IF(NOT(ISBLANK(DATA!A335)),"INSERT INTO SYSADM.PSAUTHITEM VALUES ('"&$B$1&DATA!A335&"_VW', '"&DATA!D316&"', '"&DATA!E316&"', '"&DATA!F316&"', '"&DATA!G316&"', 1, "&DATA!K337&");","")
A339: =IF(NOT(ISBLANK(DATA!A336)),"INSERT INTO SYSADM.PSAUTHITEM VALUES ('"&$B$1&DATA!A336&"_VW', '"&DATA!D317&"', '"&DATA!E317&"', '"&DATA!F317&"', '"&DATA!G317&"', 1, "&DATA!K338&");","")
...

Sheet PSAUTHITEM_C
A1: Prefix: | B1: =Prefix -> UCCS_UXDSP_
A3: SQL Statement
A4: =IF(NOT(ISBLANK(DATA!A4)),IF(DATA!#REF!>7,"INSERT INTO SYSADM.PSAUTHITEM VALUES ('"&$B$1&DATA!A4&IF(ISEVEN(DATA!#REF!),"_C' ,","_AC', ")&"'"&DATA!#REF!&"', '"&DATA!#REF!&"', '"&DATA!#REF!&"', '"&DATA!#REF!&"', 0, "&DATA!#REF!&");",""),"") -> #REF!
A5: =IF(NOT(ISBLANK(DATA!A5)),IF(DATA!#REF!>7,"INSERT INTO SYSADM.PSAUTHITEM VALUES ('"&$B$1&DATA!A5&IF(ISEVEN(DATA!#REF!),"_C' ,","_AC', ")&"'"&DATA!#REF!&"', '"&DATA!#REF!&"', '"&DATA!#REF!&"', '"&DATA!#REF!&"', 0, "&DATA!#REF!&");",""),"") -> #REF!
A6: =IF(NOT(ISBLANK(DATA!#REF!)),IF(DATA!#REF!>7,"INSERT INTO SYSADM.PSAUTHITEM VALUES ('"&$B$1&DATA!#REF!&IF(ISEVEN(DATA!#REF!),"_C' ,","_AC', ")&"'"&DATA!#REF!&"', '"&DATA!#REF!&"', '"&DATA!#REF!&"', '"&DATA!#REF!&"', 0, "&DATA!#REF!&");",""),"") -> #REF!
A7: =IF(NOT(ISBLANK(DATA!#REF!)),IF(DATA!#REF!>7,"INSERT INTO SYSADM.PSAUTHITEM VALUES ('"&$B$1&DATA!#REF!&IF(ISEVEN(DATA!#REF!),"_C' ,","_AC', ")&"'"&DATA!#REF!&"', '"&DATA!#REF!&"', '"&DATA!#REF!&"', '"&DATA!#REF!&"', 0, "&DATA!#REF!&");",""),"") -> #REF!
A8: =IF(NOT(ISBLANK(DATA!A6)),IF(DATA!#REF!>7,"INSERT INTO SYSADM.PSAUTHITEM VALUES ('"&$B$1&DATA!A6&IF(ISEVEN(DATA!#REF!),"_C' ,","_AC', ")&"'"&DATA!#REF!&"', '"&DATA!#REF!&"', '"&DATA!#REF!&"', '"&DATA!#REF!&"', 0, "&DATA!#REF!&");",""),"") -> #REF!
A9: =IF(NOT(ISBLANK(DATA!A7)),IF(DATA!#REF!>7,"INSERT INTO SYSADM.PSAUTHITEM VALUES ('"&$B$1&DATA!A7&IF(ISEVEN(DATA!#REF!),"_C' ,","_AC', ")&"'"&DATA!#REF!&"', '"&DATA!#REF!&"', '"&DATA!#REF!&"', '"&DATA!#REF!&"', 0, "&DATA!#REF!&");",""),"") -> #REF!
A10: =IF(NOT(ISBLANK(DATA!A8)),IF(DATA!#REF!>7,"INSERT INTO SYSADM.PSAUTHITEM VALUES ('"&$B$1&DATA!A8&IF(ISEVEN(DATA!#REF!),"_C' ,","_AC', ")&"'"&DATA!#REF!&"', '"&DATA!#REF!&"', '"&DATA!#REF!&"', '"&DATA!#REF!&"', 0, "&DATA!#REF!&");",""),"") -> #REF!
A11: =IF(NOT(ISBLANK(DATA!A9)),IF(DATA!#REF!>7,"INSERT INTO SYSADM.PSAUTHITEM VALUES ('"&$B$1&DATA!A9&IF(ISEVEN(DATA!#REF!),"_C' ,","_AC', ")&"'"&DATA!#REF!&"', '"&DATA!#REF!&"', '"&DATA!#REF!&"', '"&DATA!#REF!&"', 0, "&DATA!#REF!&");",""),"") -> #REF!
A12: =IF(NOT(ISBLANK(DATA!A10)),IF(DATA!#REF!>7,"INSERT INTO SYSADM.PSAUTHITEM VALUES ('"&$B$1&DATA!A10&IF(ISEVEN(DATA!#REF!),"_C' ,","_AC', ")&"'"&DATA!#REF!&"', '"&DATA!#REF!&"', '"&DATA!#REF!&"', '"&DATA!#REF!&"', 0, "&DATA!#REF!&");",""),"") -> #REF!
A13: =IF(NOT(ISBLANK(DATA!A11)),IF(DATA!#REF!>7,"INSERT INTO SYSADM.PSAUTHITEM VALUES ('"&$B$1&DATA!A11&IF(ISEVEN(DATA!#REF!),"_C' ,","_AC', ")&"'"&DATA!#REF!&"', '"&DATA!#REF!&"', '"&DATA!#REF!&"', '"&DATA!#REF!&"', 0, "&DATA!#REF!&");",""),"") -> #REF!
A14: =IF(NOT(ISBLANK(DATA!A12)),IF(DATA!#REF!>7,"INSERT INTO SYSADM.PSAUTHITEM VALUES ('"&$B$1&DATA!A12&IF(ISEVEN(DATA!#REF!),"_C' ,","_AC', ")&"'"&DATA!#REF!&"', '"&DATA!#REF!&"', '"&DATA!#REF!&"', '"&DATA!#REF!&"', 0, "&DATA!#REF!&");",""),"") -> #REF!
A15: =IF(NOT(ISBLANK(DATA!A13)),IF(DATA!#REF!>7,"INSERT INTO SYSADM.PSAUTHITEM VALUES ('"&$B$1&DATA!A13&IF(ISEVEN(DATA!#REF!),"_C' ,","_AC', ")&"'"&DATA!#REF!&"', '"&DATA!#REF!&"', '"&DATA!#REF!&"', '"&DATA!#REF!&"', 0, "&DATA!#REF!&");",""),"") -> #REF!
A16: =IF(NOT(ISBLANK(DATA!A14)),IF(DATA!#REF!>7,"INSERT INTO SYSADM.PSAUTHITEM VALUES ('"&$B$1&DATA!A14&IF(ISEVEN(DATA!#REF!),"_C' ,","_AC', ")&"'"&DATA!#REF!&"', '"&DATA!#REF!&"', '"&DATA!#REF!&"', '"&DATA!#REF!&"', 0, "&DATA!#REF!&");",""),"") -> #REF!
A17: =IF(NOT(ISBLANK(DATA!A15)),IF(DATA!#REF!>7,"INSERT INTO SYSADM.PSAUTHITEM VALUES ('"&$B$1&DATA!A15&IF(ISEVEN(DATA!#REF!),"_C' ,","_AC', ")&"'"&DATA!#REF!&"', '"&DATA!#REF!&"', '"&DATA!#REF!&"', '"&DATA!#REF!&"', 0, "&DATA!#REF!&");",""),"") -> #REF!
A18: =IF(NOT(ISBLANK(DATA!A16)),IF(DATA!#REF!>7,"INSERT INTO SYSADM.PSAUTHITEM VALUES ('"&$B$1&DATA!A16&IF(ISEVEN(DATA!#REF!),"_C' ,","_AC', ")&"'"&DATA!#REF!&"', '"&DATA!#REF!&"', '"&DATA!#REF!&"', '"&DATA!#REF!&"', 0, "&DATA!#REF!&");",""),"") -> #REF!
A19: =IF(NOT(ISBLANK(DATA!A17)),IF(DATA!#REF!>7,"INSERT INTO SYSADM.PSAUTHITEM VALUES ('"&$B$1&DATA!A17&IF(ISEVEN(DATA!#REF!),"_C' ,","_AC', ")&"'"&DATA!#REF!&"', '"&DATA!#REF!&"', '"&DATA!#REF!&"', '"&DATA!#REF!&"', 0, "&DATA!#REF!&");",""),"") -> #REF!
... A24: =IF(NOT(ISBLANK(DATA!A22)),IF(DATA!#REF!>7,"INSERT INTO SYSADM.PSAUTHITEM VALUES ('"&$B$1&DATA!A22&IF(ISEVEN(DATA!#REF!),"_C' ,","_AC', ")&"'"&DATA!#REF!&"', '"&DATA!#REF!&"', '"&DATA!#REF!&"', '"&DATA!#REF!&"', 0, "&DATA!#REF!&");",""),"") -> #REF!
A25: =IF(NOT(ISBLANK(DATA!A23)),IF(DATA!I4>7,"INSERT INTO SYSADM.PSAUTHITEM VALUES ('"&$B$1&DATA!A23&IF(ISEVEN(DATA!J4),"_C' ,","_AC', ")&"'"&DATA!D4&"', '"&DATA!E4&"', '"&DATA!F4&"', '"&DATA!G4&"', 0, "&DATA!I4&");",""),"")
A26: =IF(NOT(ISBLANK(DATA!A24)),IF(DATA!I5>7,"INSERT INTO SYSADM.PSAUTHITEM VALUES ('"&$B$1&DATA!A24&IF(ISEVEN(DATA!J5),"_C' ,","_AC', ")&"'"&DATA!D5&"', '"&DATA!E5&"', '"&DATA!F5&"', '"&DATA!G5&"', 0, "&DATA!I5&");",""),"")
A27: =IF(NOT(ISBLANK(DATA!A25)),IF(DATA!I6>7,"INSERT INTO SYSADM.PSAUTHITEM VALUES ('"&$B$1&DATA!A25&IF(ISEVEN(DATA!J6),"_C' ,","_AC', ")&"'"&DATA!D6&"', '"&DATA!E6&"', '"&DATA!F6&"', '"&DATA!G6&"', 0, "&DATA!I6&");",""),"")
A28: =IF(NOT(ISBLANK(DATA!A26)),IF(DATA!I7>7,"INSERT INTO SYSADM.PSAUTHITEM VALUES ('"&$B$1&DATA!A26&IF(ISEVEN(DATA!J7),"_C' ,","_AC', ")&"'"&DATA!D7&"', '"&DATA!E7&"', '"&DATA!F7&"', '"&DATA!G7&"', 0, "&DATA!I7&");",""),"")
A29: =IF(NOT(ISBLANK(DATA!A27)),IF(DATA!I8>7,"INSERT INTO SYSADM.PSAUTHITEM VALUES ('"&$B$1&DATA!A27&IF(ISEVEN(DATA!J8),"_C' ,","_AC', ")&"'"&DATA!D8&"', '"&DATA!E8&"', '"&DATA!F8&"', '"&DATA!G8&"', 0, "&DATA!I8&");",""),"")
A30: =IF(NOT(ISBLANK(DATA!A28)),IF(DATA!I9>7,"INSERT INTO SYSADM.PSAUTHITEM VALUES ('"&$B$1&DATA!A28&IF(ISEVEN(DATA!J9),"_C' ,","_AC', ")&"'"&DATA!D9&"', '"&DATA!E9&"', '"&DATA!F9&"', '"&DATA!G9&"', 0, "&DATA!I9&");",""),"") -> INSERT INTO SYSADM.PSAUTHITEM VALUES ('UCCS_UXDSP_STDNT_DISBLTY_SUPV2_C' ,'CC_BIO_DEMO_DATA_STDNT', 'INQUIRE', 'SCC_ADDR_PERS_INQ', 'SCC_ADDR_PERS_INQ', 0, 8);
A31: =IF(NOT(ISBLANK(DATA!A29)),IF(DATA!I10>7,"INSERT INTO SYSADM.PSAUTHITEM VALUES ('"&$B$1&DATA!A29&IF(ISEVEN(DATA!J10),"_C' ,","_AC', ")&"'"&DATA!D10&"', '"&DATA!E10&"', '"&DATA!F10&"', '"&DATA!G10&"', 0, "&DATA!I10&");",""),"") -> INSERT INTO SYSADM.PSAUTHITEM VALUES ('UCCS_UXDSP_STDNT_DISBLTY_SUPV2_C' ,'CC_BIO_DEMO_DATA_STDNT', 'INQUIRE', 'SCC_EADDR_PERS_INQ', 'SCC_EADDR_PERS_INQ', 0, 8);
A32: =IF(NOT(ISBLANK(DATA!A30)),IF(DATA!I11>7,"INSERT INTO SYSADM.PSAUTHITEM VALUES ('"&$B$1&DATA!A30&IF(ISEVEN(DATA!J11),"_C' ,","_AC', ")&"'"&DATA!D11&"', '"&DATA!E11&"', '"&DATA!F11&"', '"&DATA!G11&"', 0, "&DATA!I11&");",""),"") -> INSERT INTO SYSADM.PSAUTHITEM VALUES ('UCCS_UXDSP_STDNT_DISBLTY_SUPV2_C' ,'CC_BIO_DEMO_DATA_STDNT', 'INQUIRE', 'SCC_NAMES_INQ', 'SCC_NAMES_INQ', 0, 8);
A33: =IF(NOT(ISBLANK(DATA!A31)),IF(DATA!I12>7,"INSERT INTO SYSADM.PSAUTHITEM VALUES ('"&$B$1&DATA!A31&IF(ISEVEN(DATA!J12),"_C' ,","_AC', ")&"'"&DATA!D12&"', '"&DATA!E12&"', '"&DATA!F12&"', '"&DATA!G12&"', 0, "&DATA!I12&");",""),"") -> INSERT INTO SYSADM.PSAUTHITEM VALUES ('UCCS_UXDSP_STDNT_DISBLTY_SUPV2_C' ,'CC_BIO_DEMO_DATA_STDNT', 'INQUIRE', 'SCC_PHONE_PERS_INQ', 'SCC_PHONE_PERS_INQ', 0, 8);
A34: =IF(NOT(ISBLANK(DATA!A32)),IF(DATA!I13>7,"INSERT INTO SYSADM.PSAUTHITEM VALUES ('"&$B$1&DATA!A32&IF(ISEVEN(DATA!J13),"_C' ,","_AC', ")&"'"&DATA!D13&"', '"&DATA!E13&"', '"&DATA!F13&"', '"&DATA!G13&"', 0, "&DATA!I13&");",""),"")
A35: =IF(NOT(ISBLANK(DATA!A33)),IF(DATA!I14>7,"INSERT INTO SYSADM.PSAUTHITEM VALUES ('"&$B$1&DATA!A33&IF(ISEVEN(DATA!J14),"_C' ,","_AC', ")&"'"&DATA!D14&"', '"&DATA!E14&"', '"&DATA!F14&"', '"&DATA!G14&"', 0, "&DATA!I14&");",""),"")
A36: =IF(NOT(ISBLANK(DATA!A34)),IF(DATA!I15>7,"INSERT INTO SYSADM.PSAUTHITEM VALUES ('"&$B$1&DATA!A34&IF(ISEVEN(DATA!J15),"_C' ,","_AC', ")&"'"&DATA!D15&"', '"&DATA!E15&"', '"&DATA!F15&"', '"&DATA!G15&"', 0, "&DATA!I15&");",""),"")
... A331: =IF(NOT(ISBLANK(DATA!A329)),IF(DATA!I310>7,"INSERT INTO SYSADM.PSAUTHITEM VALUES ('"&$B$1&DATA!A329&IF(ISEVEN(DATA!J310),"_C' ,","_AC', ")&"'"&DATA!D310&"', '"&DATA!E310&"', '"&DATA!F310&"', '"&DATA!G310&"', 0, "&DATA!I310&");",""),"")
A332: =IF(NOT(ISBLANK(DATA!#REF!)),IF(DATA!#REF!>7,"INSERT INTO SYSADM.PSAUTHITEM VALUES ('"&$B$1&DATA!#REF!&IF(ISEVEN(DATA!#REF!),"_C' ,","_AC', ")&"'"&DATA!#REF!&"', '"&DATA!#REF!&"', '"&DATA!#REF!&"', '"&DATA!#REF!&"', 0, "&DATA!#REF!&");",""),"") -> #REF!
A333: =IF(NOT(ISBLANK(DATA!A330)),IF(DATA!I311>7,"INSERT INTO SYSADM.PSAUTHITEM VALUES ('"&$B$1&DATA!A330&IF(ISEVEN(DATA!J311),"_C' ,","_AC', ")&"'"&DATA!D311&"', '"&DATA!E311&"', '"&DATA!F311&"', '"&DATA!G311&"', 0, "&DATA!I311&");",""),"")
A334: =IF(NOT(ISBLANK(DATA!A331)),IF(DATA!I312>7,"INSERT INTO SYSADM.PSAUTHITEM VALUES ('"&$B$1&DATA!A331&IF(ISEVEN(DATA!J312),"_C' ,","_AC', ")&"'"&DATA!D312&"', '"&DATA!E312&"', '"&DATA!F312&"', '"&DATA!G312&"', 0, "&DATA!I312&");",""),"")
A335: =IF(NOT(ISBLANK(DATA!A332)),IF(DATA!I313>7,"INSERT INTO SYSADM.PSAUTHITEM VALUES ('"&$B$1&DATA!A332&IF(ISEVEN(DATA!J313),"_C' ,","_AC', ")&"'"&DATA!D313&"', '"&DATA!E313&"', '"&DATA!F313&"', '"&DATA!G313&"', 0, "&DATA!I313&");",""),"")
A336: =IF(NOT(ISBLANK(DATA!A333)),IF(DATA!I314>7,"INSERT INTO SYSADM.PSAUTHITEM VALUES ('"&$B$1&DATA!A333&IF(ISEVEN(DATA!J314),"_C' ,","_AC', ")&"'"&DATA!D314&"', '"&DATA!E314&"', '"&DATA!F314&"', '"&DATA!G314&"', 0, "&DATA!I314&");",""),"")
A337: =IF(NOT(ISBLANK(DATA!A334)),IF(DATA!I315>7,"INSERT INTO SYSADM.PSAUTHITEM VALUES ('"&$B$1&DATA!A334&IF(ISEVEN(DATA!J315),"_C' ,","_AC', ")&"'"&DATA!D315&"', '"&DATA!E315&"', '"&DATA!F315&"', '"&DATA!G315&"', 0, "&DATA!I315&");",""),"")
A338: =IF(NOT(ISBLANK(DATA!A335)),IF(DATA!I316>7,"INSERT INTO SYSADM.PSAUTHITEM VALUES ('"&$B$1&DATA!A335&IF(ISEVEN(DATA!J316),"_C' ,","_AC', ")&"'"&DATA!D316&"', '"&DATA!E316&"', '"&DATA!F316&"', '"&DATA!G316&"', 0, "&DATA!I316&");",""),"")
